<mujoco model="H2">
  <compiler angle="radian" meshdir="meshes"/>

  <default>
    <joint damping="0.001" armature="0.01" frictionloss="0.1"/>
    <default class="collision">
      <geom group="0" rgba="0.2 0.7 0.2 1"/>
    </default>
    <geom condim='4' contype="1" conaffinity="15" solref='0.001 2' friction='1 0 0'/>
  </default>
  
  <asset>
    <mesh name="pelvis" file="pelvis.stl"/>
    <mesh name="waist_yaw_link" file="waist_yaw_link.stl"/>
    <mesh name="waist_roll_link" file="waist_roll_link.stl"/>
    <mesh name="torso_link" file="torso_link.stl"/>
    <mesh name="head_pitch_link" file="head_pitch_link.stl"/>
    <mesh name="head_yaw_link" file="head_yaw_link.stl"/>
    <mesh name="right_shoulder_pitch_link" file="right_shoulder_pitch_link.stl"/>
    <mesh name="right_shoulder_roll_link" file="right_shoulder_roll_link.stl"/>
    <mesh name="right_shoulder_yaw_link" file="right_shoulder_yaw_link.stl"/>
    <mesh name="right_elbow_link" file="right_elbow_link.stl"/>
    <mesh name="right_wrist_roll_link" file="right_wrist_roll_link.stl"/>
    <mesh name="right_wrist_pitch_link" file="right_wrist_pitch_link.stl"/>
    <mesh name="right_wrist_yaw_link" file="right_wrist_yaw_link.stl"/>
    <mesh name="left_shoulder_pitch_link" file="left_shoulder_pitch_link.stl"/>
    <mesh name="left_shoulder_roll_link" file="left_shoulder_roll_link.stl"/>
    <mesh name="left_shoulder_yaw_link" file="left_shoulder_yaw_link.stl"/>
    <mesh name="left_elbow_link" file="left_elbow_link.stl"/>
    <mesh name="left_wrist_roll_link" file="left_wrist_roll_link.stl"/>
    <mesh name="left_wrist_pitch_link" file="left_wrist_pitch_link.stl"/>
    <mesh name="left_wrist_yaw_link" file="left_wrist_yaw_link.stl"/>
    <mesh name="left_hip_pitch_link" file="left_hip_pitch_link.stl"/>
    <mesh name="left_hip_roll_link" file="left_hip_roll_link.stl"/>
    <mesh name="left_hip_yaw_link" file="left_hip_yaw_link.stl"/>
    <mesh name="left_knee_link" file="left_knee_link.stl"/>
    <mesh name="left_ankle_roll_link" file="left_ankle_roll_link.stl"/>
    <mesh name="left_ankle_pitch_link" file="left_ankle_pitch_link.stl"/>
    <mesh name="right_hip_pitch_link" file="right_hip_pitch_link.stl"/>
    <mesh name="right_hip_roll_link" file="right_hip_roll_link.stl"/>
    <mesh name="right_hip_yaw_link" file="right_hip_yaw_link.stl"/>
    <mesh name="right_knee_link" file="right_knee_link.stl"/>
    <mesh name="right_ankle_roll_link" file="right_ankle_roll_link.stl"/>
    <mesh name="right_ankle_pitch_link" file="right_ankle_pitch_link.stl"/>
  </asset>

  <worldbody>
    <body name="pelvis" pos="0 0 1.0329">
      <inertial pos="0.00046244 -4.214e-05 -0.0147344" quat="0.707546 0.706201 -0.0235095 -0.0102787" mass="7.60468" diaginertia="0.0355137 0.0275324 0.0228779"/>
      <joint name="floating_base_joint" type="free" limited="false" actuatorfrclimited="false"/>
      <geom type="mesh" contype="0" conaffinity="0" group="1" density="0" rgba="0.7 0.7 0.7 1" mesh="pelvis"/>
      <geom type="mesh" rgba="0.7 0.7 0.7 1" mesh="pelvis"/>
      <site name="imu_in_pelvis" size="0.01" pos="0.04525 0 -0.08339"/>
      <body name="waist_yaw_link" pos="0 0.0015099 0.090537">
        <inertial pos="0.00626994 0 0.0169696" quat="0 0.717728 0 0.696323" mass="0.279762" diaginertia="0.000311422 0.0002473 0.000123348"/>
        <joint name="waist_yaw_joint" pos="0 0 0" axis="0 0 1" range="-1.7453 1.7453" actuatorfrcrange="-120 120"/>
        <geom type="mesh" contype="0" conaffinity="0" group="1" density="0" rgba="0.7 0.7 0.7 1" mesh="waist_yaw_link"/>
        <body name="waist_roll_link" pos="0 -0.0015099 0.0325">
          <inertial pos="0 0.00128474 0" quat="0 0.707107 0 0.707107" mass="0.0658504" diaginertia="1.58e-05 1.041e-05 8.09e-06"/>
          <joint name="waist_roll_joint" pos="0 0 0" axis="1 0 0" range="-0.5236 0.5236" actuatorfrcrange="-180 180"/>
          <geom type="mesh" contype="0" conaffinity="0" group="1" density="0" rgba="0.7 0.7 0.7 1" mesh="waist_roll_link"/>
          <body name="torso_link">
            <inertial pos="0.0134247 0.0054719 0.210501" quat="0.999399 -0.0341887 0.00399831 0.00403179" mass="15.8703" diaginertia="0.273064 0.244383 0.0840858"/>
            <joint name="waist_pitch_joint" pos="0 0 0" axis="0 1 0" range="-0.43633 0.5236" actuatorfrcrange="-180 180"/>
            <geom type="mesh" contype="0" conaffinity="0" group="1" density="0" rgba="0.7 0.7 0.7 1" mesh="torso_link"/>
            <geom type="mesh" rgba="0.7 0.7 0.7 1" mesh="torso_link"/>
            <site name="imu_in_torso" size="0.01" pos="-0.03959 -0.00224 0.14792"/>
            <body name="head_pitch_link" pos="-0.00011475 0.020709 0.42181">
              <inertial pos="5.279e-08 -0.00035318 0.045125" quat="0.999996 -0.000955249 -0.00262397 -0.000580497" mass="1.82" diaginertia="0.00538697 0.00532442 0.00140982"/>
              <joint name="head_pitch_joint" pos="0 0 0" axis="0 1 0" range="-0.5236 0.83775" actuatorfrcrange="-50 50"/>
              <geom type="mesh" contype="0" conaffinity="0" group="1" density="0" rgba="0.7 0.7 0.7 1" mesh="head_pitch_link"/>
              <body name="head_yaw_link" pos="0 -0.0189 0.1325">
                <inertial pos="0.0219 0 0.0187" quat="0.667311 -0.227767 -0.231751 0.670156" mass="1.3" diaginertia="0.00535274 0.00472336 0.00378091"/>
                <joint name="head_yaw_joint" pos="0 0 0" axis="0 0 1" range="-1.7453 1.7453" actuatorfrcrange="-50 50"/>
                <geom type="mesh" contype="0" conaffinity="0" group="1" density="0" rgba="0.7 0.7 0.7 1" mesh="head_yaw_link"/>
                <geom type="mesh" rgba="0.7 0.7 0.7 1" mesh="head_yaw_link"/>
              </body>
            </body>
            <body name="right_shoulder_pitch_link" pos="0.0019706 -0.11185 0.35789" quat="0.990959 -0.134164 0 0">
              <inertial pos="0.00296153 -0.0520268 -0.025045" quat="0.955852 -0.291379 -0.0379149 -0.00289698" mass="1.06056" diaginertia="0.00122192 0.00110581 0.000458835"/>
              <joint name="right_shoulder_pitch_joint" pos="0 0 0" axis="0 1 0" range="-2.61799 1.8326" actuatorfrcrange="-120 120"/>
              <geom type="mesh" contype="0" conaffinity="0" group="1" density="0" rgba="0.7 0.7 0.7 1" mesh="right_shoulder_pitch_link"/>
              <geom type="mesh" rgba="0.7 0.7 0.7 1" mesh="right_shoulder_pitch_link"/>
              <body name="right_shoulder_roll_link" pos="-0.00082577 -0.060403 -0.040059" quat="0.990959 0.134164 0 0">
                <inertial pos="0 -0.00415443 -0.0629422" quat="0.722138 0.0778018 0.110828 0.678366" mass="1.34511" diaginertia="0.00210225 0.00198513 0.00105666"/>
                <joint name="right_shoulder_roll_joint" pos="0 0 0" axis="1 0 0" range="-2.63545 0.516617" actuatorfrcrange="-54 54"/>
                <geom type="mesh" contype="0" conaffinity="0" group="1" density="0" rgba="0.7 0.7 0.7 1" mesh="right_shoulder_roll_link"/>
                <geom type="mesh" rgba="0.7 0.7 0.7 1" mesh="right_shoulder_roll_link"/>
                <body name="right_shoulder_yaw_link" pos="-0.0025949 -0.0037808 -0.096231">
                  <inertial pos="0.00364187 -0.0186515 -0.0558555" quat="0.995617 0.0729116 -0.0584518 0.00371547" mass="0.915717" diaginertia="0.00306267 0.00257349 0.00143042"/>
                  <joint name="right_shoulder_yaw_joint" pos="0 0 0" axis="0 0 1" range="-2.61799 2.61799" actuatorfrcrange="-54 54"/>
                  <geom type="mesh" contype="0" conaffinity="0" group="1" density="0" rgba="0.7 0.7 0.7 1" mesh="right_shoulder_yaw_link"/>
                  <geom type="mesh" rgba="0.7 0.7 0.7 1" mesh="right_shoulder_yaw_link"/>
                  <body name="right_elbow_link" pos="0.015346 -0.020599 -0.13363">
                    <inertial pos="0.0459969 0.0283296 -0.00661325" quat="0.463074 0.507638 0.507229 0.520177" mass="1.69432" diaginertia="0.00548751 0.00533836 0.000695052"/>
                    <joint name="right_elbow_joint" pos="0 0 0" axis="0 1 0" range="-0.986111 3.07178" actuatorfrcrange="-54 54"/>
                    <geom type="mesh" contype="0" conaffinity="0" group="1" density="0" rgba="0.7 0.7 0.7 1" mesh="right_elbow_link"/>
                    <geom type="mesh" rgba="0.7 0.7 0.7 1" mesh="right_elbow_link"/>
                    <body name="right_wrist_roll_link" pos="0.13177 0.021197 -0.013782">
                      <inertial pos="0.0337195 -0.00237482 0.00031544" quat="0.242945 0.638599 -0.286806 0.671499" mass="0.969837" diaginertia="0.000926999 0.000903832 0.000852829"/>
                      <joint name="right_wrist_roll_joint" pos="0 0 0" axis="1 0 0" range="-2.61799 2.61799" actuatorfrcrange="-54 54"/>
                      <geom type="mesh" contype="0" conaffinity="0" group="1" density="0" rgba="0.7 0.7 0.7 1" mesh="right_wrist_roll_link"/>
                      <body name="right_wrist_pitch_link" pos="0.076351 -0.00015864 0.0011464">
                        <inertial pos="0.01821 -0.0314035 0.0115687" quat="0.977698 0.037912 -0.203807 -0.033629" mass="0.946953" diaginertia="0.000918192 0.00082104 0.000648419"/>
                        <joint name="right_wrist_pitch_joint" pos="0 0 0" axis="0 1 0" range="-0.436332 0.436332" actuatorfrcrange="-25 25"/>
                        <geom type="mesh" contype="0" conaffinity="0" group="1" density="0" rgba="0.7 0.7 0.7 1" mesh="right_wrist_pitch_link"/>
                        <body name="right_wrist_yaw_link" pos="0.028195 5.8414e-05 -0.0012184">
                          <inertial pos="-0.0101173 -0.00400457 -0.0173071" quat="0.382961 0.585065 0.450933 0.554707" mass="0.605752" diaginertia="0.000778685 0.00067164 0.000238076"/>
                          <joint name="right_wrist_yaw_joint" pos="0 0 0" axis="0 0 1" range="-1.22173 1.22173" actuatorfrcrange="-25 25"/>
                          <geom type="mesh" contype="0" conaffinity="0" group="1" density="0" rgba="0.7 0.7 0.7 1" mesh="right_wrist_yaw_link"/>
                          <geom type="mesh" rgba="0.7 0.7 0.7 1" mesh="right_wrist_yaw_link"/>
                        </body>
                      </body>
                    </body>
                  </body>
                </body>
              </body>
            </body>
            <body name="left_shoulder_pitch_link" pos="0.0019779 0.11553 0.35792" quat="0.990959 0.134164 0 0">
              <inertial pos="0.00296153 0.0520268 -0.025045" quat="0.955852 0.29138 -0.0379121 0.00288293" mass="1.06056" diaginertia="0.00122192 0.00110581 0.000458834"/>
              <joint name="left_shoulder_pitch_joint" pos="0 0 0" axis="0 1 0" range="-2.61799 1.8326" actuatorfrcrange="-120 120"/>
              <geom type="mesh" contype="0" conaffinity="0" group="1" density="0" rgba="0.7 0.7 0.7 1" mesh="left_shoulder_pitch_link"/>
              <geom type="mesh" rgba="0.7 0.7 0.7 1" mesh="left_shoulder_pitch_link"/>
              <body name="left_shoulder_roll_link" pos="-0.00082158 0.060413 -0.040043" quat="0.990959 -0.134164 0 0">
                <inertial pos="0 0.00415443 -0.0629422" quat="0.678366 0.110828 0.0778018 0.722138" mass="1.34511" diaginertia="0.00210225 0.00198513 0.00105666"/>
                <joint name="left_shoulder_roll_joint" pos="0 0 0" axis="1 0 0" range="-0.516617 2.63545" actuatorfrcrange="-54 54"/>
                <geom type="mesh" contype="0" conaffinity="0" group="1" density="0" rgba="0.7 0.7 0.7 1" mesh="left_shoulder_roll_link"/>
                <geom type="mesh" rgba="0.7 0.7 0.7 1" mesh="left_shoulder_roll_link"/>
                <body name="left_shoulder_yaw_link" pos="-0.0025946 0.0038061 -0.09623">
                  <inertial pos="0.00364187 0.0186515 -0.0558555" quat="0.995617 -0.0729116 -0.0584518 -0.00371547" mass="0.915717" diaginertia="0.00306267 0.00257349 0.00143042"/>
                  <joint name="left_shoulder_yaw_joint" pos="0 0 0" axis="0 0 1" range="-2.61799 2.61799" actuatorfrcrange="-54 54"/>
                  <geom type="mesh" contype="0" conaffinity="0" group="1" density="0" rgba="0.7 0.7 0.7 1" mesh="left_shoulder_yaw_link"/>
                  <geom type="mesh" rgba="0.7 0.7 0.7 1" mesh="left_shoulder_yaw_link"/>
                  <body name="left_elbow_link" pos="0.015424 0.020635 -0.13364">
                    <inertial pos="0.0459969 -0.0283296 -0.00661325" quat="0.520177 0.507229 0.507638 0.463074" mass="1.69432" diaginertia="0.00548751 0.00533836 0.000695052"/>
                    <joint name="left_elbow_joint" pos="0 0 0" axis="0 1 0" range="-0.986111 3.07178" actuatorfrcrange="-54 54"/>
                    <geom type="mesh" contype="0" conaffinity="0" group="1" density="0" rgba="0.7 0.7 0.7 1" mesh="left_elbow_link"/>
                    <geom type="mesh" rgba="0.7 0.7 0.7 1" mesh="left_elbow_link"/>
                    <body name="left_wrist_roll_link" pos="0.13119 -0.021207 -0.013343">
                      <inertial pos="0.0337195 0.00237482 0.00031544" quat="-0.242945 0.638599 0.286806 0.671499" mass="0.969837" diaginertia="0.000926999 0.000903832 0.000852829"/>
                      <joint name="left_wrist_roll_joint" pos="0 0 0" axis="1 0 0" range="-2.61799 2.61799" actuatorfrcrange="-54 54"/>
                      <geom type="mesh" contype="0" conaffinity="0" group="1" density="0" rgba="0.7 0.7 0.7 1" mesh="left_wrist_roll_link"/>
                      <body name="left_wrist_pitch_link" pos="0.080589 3.0398e-05 -0.0013317">
                        <inertial pos="0.01821 0.0314035 0.0115687" quat="0.977698 -0.037912 -0.203807 0.033629" mass="0.946953" diaginertia="0.000918192 0.00082104 0.000648419"/>
                        <joint name="left_wrist_pitch_joint" pos="0 0 0" axis="0 1 0" range="-0.436332 0.436332" actuatorfrcrange="-25 25"/>
                        <geom type="mesh" contype="0" conaffinity="0" group="1" density="0" rgba="0.7 0.7 0.7 1" mesh="left_wrist_pitch_link"/>
                        <body name="left_wrist_yaw_link" pos="0.028225 0.00048901 0.00058318">
                          <inertial pos="-0.0101173 0.00400457 -0.0173071" quat="0.554707 0.450933 0.585065 0.382961" mass="0.605752" diaginertia="0.000778685 0.00067164 0.000238076"/>
                          <joint name="left_wrist_yaw_joint" pos="0 0 0" axis="0 0 1" range="-1.22173 1.22173" actuatorfrcrange="-25 25"/>
                          <geom type="mesh" contype="0" conaffinity="0" group="1" density="0" rgba="0.7 0.7 0.7 1" mesh="left_wrist_yaw_link"/>
                          <geom type="mesh" rgba="0.7 0.7 0.7 1" mesh="left_wrist_yaw_link"/>
                        </body>
                      </body>
                    </body>
                  </body>
                </body>
              </body>
            </body>
          </body>
        </body>
      </body>
      <body name="left_hip_pitch_link" pos="0 0.0819279 -0.043723" quat="0.965926 -0.25882 0 0">
        <inertial pos="0.00300595 0.0593147 -0.0170915" quat="0.899485 0.435934 -0.0222136 -0.0198741" mass="2.79753" diaginertia="0.00510297 0.00410085 0.0034593"/>
        <joint name="left_hip_pitch_joint" pos="0 0 0" axis="0 1 0" range="-2.4526 2.77542" actuatorfrcrange="-360 360"/>
        <geom type="mesh" contype="0" conaffinity="0" group="1" density="0" rgba="0.7 0.7 0.7 1" mesh="left_hip_pitch_link"/>
        <body name="left_hip_roll_link" pos="0.018422 0.0635 -0.022095" quat="0.965926 0.25882 0 0">
          <inertial pos="-0.0302619 -0.0046893 -0.0444985" quat="-0.0935812 0.633472 -0.0477755 0.766598" mass="0.627146" diaginertia="0.00200252 0.00167509 0.00128023"/>
          <joint name="left_hip_roll_joint" pos="0 0 0" axis="1 0 0" range="-0.467441 2.16886" actuatorfrcrange="-360 360"/>
          <geom type="mesh" contype="0" conaffinity="0" group="1" density="0" rgba="0.7 0.7 0.7 1" mesh="left_hip_roll_link"/>
          <geom size="0.05" pos="-0.02 0 0" rgba="0.7 0.7 0.7 1"/>
          <body name="left_hip_yaw_link" pos="-0.0047433 -0.0057328 -0.075875">
            <inertial pos="0.00069408 -0.0108659 -0.113015" quat="0.621993 -0.0405952 0.0198637 0.781717" mass="7.08752" diaginertia="0.0514012 0.050596 0.0130067"/>
            <joint name="left_hip_yaw_joint" pos="0 0 0" axis="0 0 1" range="-2.827 2.827" actuatorfrcrange="-360 360"/>
            <geom type="mesh" contype="0" conaffinity="0" group="1" density="0" rgba="0.7 0.7 0.7 1" mesh="left_hip_yaw_link"/>
            <geom type="mesh" rgba="0.7 0.7 0.7 1" mesh="left_hip_yaw_link"/>
            <body name="left_knee_link" pos="-0.010386 -0.0042181 -0.31742">
              <inertial pos="0.00461331 0 -0.167155" quat="0.689662 0.00325283 0.00290593 0.724118" mass="3.5534" diaginertia="0.0512388 0.0510884 0.00333998"/>
              <joint name="left_knee_joint" pos="0 0 0" axis="0 1 0" range="-0.08725 2.53025" actuatorfrcrange="-360 360"/>
              <geom type="mesh" contype="0" conaffinity="0" group="1" density="0" rgba="0.7 0.7 0.7 1" mesh="left_knee_link"/>
              <geom size="0.025 0.175" pos="0.01 0 -0.25" type="cylinder" rgba="0.7 0.7 0.7 1"/>
              <body name="left_ankle_roll_link" pos="0.018383 0 -0.49662">
                <inertial pos="-0.0174063 6.424e-05 -0.0002146" quat="0.499157 0.502573 -0.497809 0.500449" mass="0.123182" diaginertia="4.00501e-05 3.43207e-05 1.44993e-05"/>
                <joint name="left_ankle_roll_joint" pos="0 0 0" axis="1 0 0" range="-0.349066 0.296706" actuatorfrcrange="-19 19"/>
                <geom type="mesh" contype="0" conaffinity="0" group="1" density="0" rgba="0.7 0.7 0.7 1" mesh="left_ankle_roll_link"/>
                <body name="left_ankle_pitch_link" pos="0 -0.0368 0">
                  <inertial pos="0.032059 0.0370053 -0.0288282" quat="6.19452e-05 0.72345 -3.0004e-05 0.690377" mass="0.844967" diaginertia="0.00438317 0.00410964 0.000599978"/>
                  <joint name="left_ankle_pitch_joint" pos="0 0 0" axis="0 1 0" range="-1.13446 0.610865" actuatorfrcrange="-66.88 66.88"/>
                  <geom type="mesh" contype="0" conaffinity="0" group="1" density="0" rgba="0.7 0.7 0.7 1" mesh="left_ankle_pitch_link"/>
                  <geom type="mesh" rgba="0.7 0.7 0.7 1" mesh="left_ankle_pitch_link"/>
                </body>
              </body>
            </body>
          </body>
        </body>
      </body>
      <body name="right_hip_pitch_link" pos="0 -0.0803801 -0.046403" quat="0.965926 0.25882 0 0">
        <inertial pos="0.00300595 -0.0593147 -0.0170915" quat="0.435934 0.899485 0.0198741 0.0222136" mass="2.79753" diaginertia="0.00510297 0.00410085 0.0034593"/>
        <joint name="right_hip_pitch_joint" pos="0 0 0" axis="0 1 0" range="-2.4526 2.77542" actuatorfrcrange="-360 360"/>
        <geom type="mesh" contype="0" conaffinity="0" group="1" density="0" rgba="0.7 0.7 0.7 1" mesh="right_hip_pitch_link"/>
        <body name="right_hip_roll_link" pos="0.037774 -0.0635 -0.019" quat="0.965926 -0.25882 0 0">
          <inertial pos="-0.0302619 0.0046893 -0.0444985" quat="0.0935812 0.633472 0.0477755 0.766598" mass="0.627146" diaginertia="0.00200252 0.00167509 0.00128023"/>
          <joint name="right_hip_roll_joint" pos="0 0 0" axis="1 0 0" range="-2.16886 0.467441" actuatorfrcrange="-360 360"/>
          <geom type="mesh" contype="0" conaffinity="0" group="1" density="0" rgba="0.7 0.7 0.7 1" mesh="right_hip_roll_link"/>
          <geom size="0.05" pos="-0.038 0 0" rgba="0.7 0.7 0.7 1"/>
          <body name="right_hip_yaw_link" pos="-0.024111 0.0057328 -0.075875">
            <inertial pos="0.00069408 0.0108659 -0.113015" quat="0.781717 0.0198637 -0.0405952 0.621993" mass="7.08752" diaginertia="0.0514012 0.050596 0.0130067"/>
            <joint name="right_hip_yaw_joint" pos="0 0 0" axis="0 0 1" range="-2.827 2.827" actuatorfrcrange="-360 360"/>
            <geom type="mesh" contype="0" conaffinity="0" group="1" density="0" rgba="0.7 0.7 0.7 1" mesh="right_hip_yaw_link"/>
            <geom type="mesh" rgba="0.7 0.7 0.7 1" mesh="right_hip_yaw_link"/>
            <body name="right_knee_link" pos="-0.010386 0.0042181 -0.31742">
              <inertial pos="0.00461331 0 -0.167155" quat="0.724118 0.00290593 0.00325283 0.689662" mass="3.5534" diaginertia="0.0512388 0.0510884 0.00333998"/>
              <joint name="right_knee_joint" pos="0 0 0" axis="0 1 0" range="-0.08725 2.53025" actuatorfrcrange="-360 360"/>
              <geom type="mesh" contype="0" conaffinity="0" group="1" density="0" rgba="0.7 0.7 0.7 1" mesh="right_knee_link"/>
              <geom size="0.025 0.175" pos="0.01 0 -0.25" type="cylinder" rgba="0.7 0.7 0.7 1"/>
              <body name="right_ankle_roll_link" pos="0.018383 0 -0.49662">
                <inertial pos="-0.0174063 -6.424e-05 -0.0002146" quat="0.502573 0.499157 -0.500449 0.497809" mass="0.123182" diaginertia="4.00501e-05 3.43207e-05 1.44993e-05"/>
                <joint name="right_ankle_roll_joint" pos="0 0 0" axis="1 0 0" range="-0.296706 0.349066" actuatorfrcrange="-19 19"/>
                <geom type="mesh" contype="0" conaffinity="0" group="1" density="0" rgba="0.7 0.7 0.7 1" mesh="right_ankle_roll_link"/>
                <body name="right_ankle_pitch_link" pos="0 0.0373 0">
                  <inertial pos="0.032059 -0.0370053 -0.0288282" quat="-6.19452e-05 0.72345 3.0004e-05 0.690377" mass="0.844967" diaginertia="0.00438317 0.00410964 0.000599978"/>
                  <joint name="right_ankle_pitch_joint" pos="0 0 0" axis="0 1 0" range="-1.13446 0.610865" actuatorfrcrange="-66.88 66.88"/>
                  <geom type="mesh" contype="0" conaffinity="0" group="1" density="0" rgba="0.7 0.7 0.7 1" mesh="right_ankle_pitch_link"/>
                  <geom type="mesh" rgba="0.7 0.7 0.7 1" mesh="right_ankle_pitch_link"/>
                </body>
              </body>
            </body>
          </body>
        </body>
      </body>
    </body>
  </worldbody>

  <actuator>
    <motor name="left_hip_pitch_joint" joint="left_hip_pitch_joint"/>
    <motor name="left_hip_roll_joint" joint="left_hip_roll_joint"/>
    <motor name="left_hip_yaw_joint" joint="left_hip_yaw_joint"/>
    <motor name="left_knee_joint" joint="left_knee_joint"/>
    <motor name="left_ankle_pitch_joint" joint="left_ankle_pitch_joint"/>
    <motor name="left_ankle_roll_joint" joint="left_ankle_roll_joint"/>
    <motor name="right_hip_pitch_joint" joint="right_hip_pitch_joint"/>
    <motor name="right_hip_roll_joint" joint="right_hip_roll_joint"/>
    <motor name="right_hip_yaw_joint" joint="right_hip_yaw_joint"/>
    <motor name="right_knee_joint" joint="right_knee_joint"/>
    <motor name="right_ankle_pitch_joint" joint="right_ankle_pitch_joint"/>
    <motor name="right_ankle_roll_joint" joint="right_ankle_roll_joint"/>
    <motor name="waist_yaw_joint" joint="waist_yaw_joint"/>
    <motor name="waist_roll_joint" joint="waist_roll_joint"/>
    <motor name="waist_pitch_joint" joint="waist_pitch_joint"/>
    <motor name="left_shoulder_pitch_joint" joint="left_shoulder_pitch_joint"/>
    <motor name="left_shoulder_roll_joint" joint="left_shoulder_roll_joint"/>
    <motor name="left_shoulder_yaw_joint" joint="left_shoulder_yaw_joint"/>
    <motor name="left_elbow_joint" joint="left_elbow_joint"/>
    <motor name="left_wrist_roll_joint" joint="left_wrist_roll_joint"/>
    <motor name="left_wrist_pitch_joint" joint="left_wrist_pitch_joint"/>
    <motor name="left_wrist_yaw_joint" joint="left_wrist_yaw_joint"/>
    <motor name="right_shoulder_pitch_joint" joint="right_shoulder_pitch_joint"/>
    <motor name="right_shoulder_roll_joint" joint="right_shoulder_roll_joint"/>
    <motor name="right_shoulder_yaw_joint" joint="right_shoulder_yaw_joint"/>
    <motor name="right_elbow_joint" joint="right_elbow_joint"/>
    <motor name="right_wrist_roll_joint" joint="right_wrist_roll_joint"/>
    <motor name="right_wrist_pitch_joint" joint="right_wrist_pitch_joint"/>
    <motor name="right_wrist_yaw_joint" joint="right_wrist_yaw_joint"/>
  </actuator>

  <sensor>
    <gyro name="imu-torso-angular-velocity" site="imu_in_torso" noise="5e-4" cutoff="34.9"/>
    <accelerometer name="imu-torso-linear-acceleration" site="imu_in_torso" noise="1e-2" cutoff="157"/>
    <gyro name="imu-pelvis-angular-velocity" site="imu_in_pelvis" noise="5e-4" cutoff="34.9"/>
    <accelerometer name="imu-pelvis-linear-acceleration" site="imu_in_pelvis" noise="1e-2" cutoff="157"/>
  </sensor>


  <!-- setup scene -->
  <statistic center="1.0 0.7 1.0" extent="0.8"/>
  <visual>
    <headlight diffuse="0.6 0.6 0.6" ambient="0.1 0.1 0.1" specular="0.9 0.9 0.9"/>
    <rgba haze="0.15 0.25 0.35 1"/>
    <global azimuth="-140" elevation="-20"/>
  </visual>
  <asset>
    <texture type="skybox" builtin="flat" rgb1="0 0 0" rgb2="0 0 0" width="512" height="3072"/>
    <texture type="2d" name="groundplane" builtin="checker" mark="edge" rgb1="0.2 0.3 0.4" rgb2="0.1 0.2 0.3" markrgb="0.8 0.8 0.8" width="300" height="300"/>
    <material name="groundplane" texture="groundplane" texuniform="true" texrepeat="5 5" reflectance="0.2"/>
  </asset>
  <worldbody>
    <light pos="1 0 3.5" dir="0 0 -1" directional="true"/>
    <geom name="floor" size="0 0 0.05" type="plane" material="groundplane"/>
  </worldbody>
</mujoco>