#usda 1.0
(
    customLayerData = {
        string creator = "URDF USD Converter v0.1.0"
    }
    defaultPrim = "g1_29dof_mode_15"
    doc = """Generated from Composed Stage of root layer /tmp/tmppzcx9bs4/g1_29dof_mode_15.usdc


Generated from Composed Stage of root layer /home/hpx/HPX_LOCO_2/mimic_baseline_2/GMT/GMT/assets/unitree_g1/usdex/g1_29dof_mode_15.usdc


Generated from Composed Stage of root layer /home/hpx/HPX_LOCO_2/mimic_baseline_2/GMT/GMT/assets/unitree_g1/temp/g1_29dof_mode_15.usd


Generated from Composed Stage of root layer /home/hpx/HPX_LOCO_2/mimic_baseline_2/GMT/GMT/assets/unitree_g1/g1_29dof_mode_15/payloads/base.usd
"""
    kilogramsPerUnit = 1
    metersPerUnit = 1
    upAxis = "Z"
)

over "g1_29dof_mode_15"
{
    over "Geometry"
    {
        over "pelvis" (
            prepend apiSchemas = ["PhysicsRigidBodyAPI", "PhysicsArticulationRootAPI", "NewtonArticulationRootAPI", "PhysicsMassAPI"]
        )
        {
            bool newton:selfCollisionEnabled = 1
            point3f physics:centerOfMass = (0, 0, -0.07605)
            float3 physics:diagonalInertia = (0.007918398, 0.0093089, 0.010549001)
            float physics:mass = 3.813
            quatf physics:principalAxes = (0.7068245, 0, 0.70738894, 0)

            over "pelvis_contour_link" (
                prepend apiSchemas = ["PhysicsRigidBodyAPI", "PhysicsMassAPI"]
            )
            {
                point3f physics:centerOfMass = (0, 0, 0)
                float3 physics:diagonalInertia = (1e-7, 1e-7, 1e-7)
                float physics:mass = 0.001
                quatf physics:principalAxes = (1, 0, 0, 0)
            }

            over "left_hip_pitch_link" (
                prepend apiSchemas = ["PhysicsRigidBodyAPI", "PhysicsMassAPI"]
            )
            {
                point3f physics:centerOfMass = (0.002741, 0.047791, -0.02606)
                float3 physics:diagonalInertia = (0.0011621179, 0.0015342169, 0.0018151652)
                float physics:mass = 1.35
                quatf physics:principalAxes = (0.69658357, -0.22916387, 0.6537957, 0.1865647)

                over "left_hip_roll_link" (
                    prepend apiSchemas = ["PhysicsRigidBodyAPI", "PhysicsMassAPI"]
                )
                {
                    point3f physics:centerOfMass = (0.029812, -0.001045, -0.087934)
                    float3 physics:diagonalInertia = (0.0014875486, 0.0024116917, 0.0025498597)
                    float physics:mass = 1.52
                    quatf physics:principalAxes = (0.8367785, 0.028566392, 0.54605055, 0.028538518)

                    over "left_hip_yaw_link" (
                        prepend apiSchemas = ["PhysicsRigidBodyAPI", "PhysicsMassAPI"]
                    )
                    {
                        point3f physics:centerOfMass = (-0.057709, -0.010981, -0.15078)
                        float3 physics:diagonalInertia = (0.0016013936, 0.0071757482, 0.007761658)
                        float physics:mass = 1.702
                        quatf physics:principalAxes = (0.64311457, 0.5827119, 0.4192163, 0.26666126)

                        over "left_knee_link" (
                            prepend apiSchemas = ["PhysicsRigidBodyAPI", "PhysicsMassAPI"]
                        )
                        {
                            point3f physics:centerOfMass = (0.005457, 0.003964, -0.12074)
                            float3 physics:diagonalInertia = (0.0014645848, 0.011277774, 0.0113804415)
                            float physics:mass = 1.932
                            quatf physics:principalAxes = (0.24699017, 0.66414475, 0.29333377, 0.6417654)

                            over "left_ankle_pitch_link" (
                                prepend apiSchemas = ["PhysicsRigidBodyAPI", "PhysicsMassAPI"]
                            )
                            {
                                point3f physics:centerOfMass = (-0.007269, 0, 0.011137)
                                float3 physics:diagonalInertia = (0.000006919497, 0.000014080503, 0.0000189)
                                float physics:mass = 0.074
                                quatf physics:principalAxes = (-0.6875043, 0.6875043, -0.16534163, 0.16534163)

                                over "left_ankle_roll_link" (
                                    prepend apiSchemas = ["PhysicsRigidBodyAPI", "PhysicsMassAPI"]
                                )
                                {
                                    point3f physics:centerOfMass = (0.026505, 0, -0.016425)
                                    float3 physics:diagonalInertia = (0.00021762145, 0.0016160998, 0.0016721786)
                                    float physics:mass = 0.608
                                    quatf physics:principalAxes = (0.99952835, -0.00077785924, -0.030700132, 0.00009749208)

                                    over "sphere" (
                                        prepend apiSchemas = ["NewtonCollisionAPI"]
                                    )
                                    {
                                    }

                                    over "sphere_1" (
                                        prepend apiSchemas = ["NewtonCollisionAPI"]
                                    )
                                    {
                                    }

                                    over "sphere_2" (
                                        prepend apiSchemas = ["NewtonCollisionAPI"]
                                    )
                                    {
                                    }

                                    over "sphere_3" (
                                        prepend apiSchemas = ["NewtonCollisionAPI"]
                                    )
                                    {
                                    }
                                }
                            }
                        }
                    }
                }
            }

            over "right_hip_pitch_link" (
                prepend apiSchemas = ["PhysicsRigidBodyAPI", "PhysicsMassAPI"]
            )
            {
                point3f physics:centerOfMass = (0.002741, -0.047791, -0.02606)
                float3 physics:diagonalInertia = (0.0011621179, 0.0015342169, 0.0018151652)
                float physics:mass = 1.35
                quatf physics:principalAxes = (0.69658357, 0.22916387, 0.6537957, -0.1865647)

                over "right_hip_roll_link" (
                    prepend apiSchemas = ["PhysicsRigidBodyAPI", "PhysicsMassAPI"]
                )
                {
                    point3f physics:centerOfMass = (0.029812, 0.001045, -0.087934)
                    float3 physics:diagonalInertia = (0.0014875486, 0.0024116917, 0.0025498597)
                    float physics:mass = 1.52
                    quatf physics:principalAxes = (0.8367785, -0.028566392, 0.54605055, -0.028538518)

                    over "right_hip_yaw_link" (
                        prepend apiSchemas = ["PhysicsRigidBodyAPI", "PhysicsMassAPI"]
                    )
                    {
                        point3f physics:centerOfMass = (-0.057709, 0.010981, -0.15078)
                        float3 physics:diagonalInertia = (0.0016013936, 0.0071757482, 0.007761658)
                        float physics:mass = 1.702
                        quatf physics:principalAxes = (0.5827119, 0.64311457, 0.26666126, 0.4192163)

                        over "right_knee_link" (
                            prepend apiSchemas = ["PhysicsRigidBodyAPI", "PhysicsMassAPI"]
                        )
                        {
                            point3f physics:centerOfMass = (0.005457, -0.003964, -0.12074)
                            float3 physics:diagonalInertia = (0.0014645212, 0.011284328, 0.01137395)
                            float physics:mass = 1.932
                            quatf physics:principalAxes = (0.6611958, 0.2457087, 0.64474386, 0.29453808)

                            over "right_ankle_pitch_link" (
                                prepend apiSchemas = ["PhysicsRigidBodyAPI", "PhysicsMassAPI"]
                            )
                            {
                                point3f physics:centerOfMass = (-0.007269, 0, 0.011137)
                                float3 physics:diagonalInertia = (0.000006919497, 0.000014080503, 0.0000189)
                                float physics:mass = 0.074
                                quatf physics:principalAxes = (-0.6875043, 0.6875043, -0.16534163, 0.16534163)

                                over "right_ankle_roll_link" (
                                    prepend apiSchemas = ["PhysicsRigidBodyAPI", "PhysicsMassAPI"]
                                )
                                {
                                    point3f physics:centerOfMass = (0.026505, 0, -0.016425)
                                    float3 physics:diagonalInertia = (0.00021762145, 0.0016160998, 0.0016721786)
                                    float physics:mass = 0.608
                                    quatf physics:principalAxes = (0.99952835, 0.00077785924, -0.030700132, -0.00009749208)

                                    over "sphere" (
                                        prepend apiSchemas = ["NewtonCollisionAPI"]
                                    )
                                    {
                                    }

                                    over "sphere_1" (
                                        prepend apiSchemas = ["NewtonCollisionAPI"]
                                    )
                                    {
                                    }

                                    over "sphere_2" (
                                        prepend apiSchemas = ["NewtonCollisionAPI"]
                                    )
                                    {
                                    }

                                    over "sphere_3" (
                                        prepend apiSchemas = ["NewtonCollisionAPI"]
                                    )
                                    {
                                    }
                                }
                            }
                        }
                    }
                }
            }

            over "waist_yaw_link" (
                prepend apiSchemas = ["PhysicsRigidBodyAPI", "PhysicsMassAPI"]
            )
            {
                point3f physics:centerOfMass = (0.003494, 0.000233, 0.018034)
                float3 physics:diagonalInertia = (0.00010220502, 0.000107714404, 0.00016353058)
                float physics:mass = 0.214
                quatf physics:principalAxes = (-0.05785514, 0.4437042, 0.8936569, 0.03401058)

                over "waist_roll_link" (
                    prepend apiSchemas = ["PhysicsRigidBodyAPI", "PhysicsMassAPI"]
                )
                {
                    point3f physics:centerOfMass = (0, 0.000023, 0)
                    float3 physics:diagonalInertia = (0.000006339, 0.000007079, 0.000008245)
                    float physics:mass = 0.086
                    quatf physics:principalAxes = (6.123234e-17, 0.70710677, 0.70710677, 0)

                    over "torso_link" (
                        prepend apiSchemas = ["PhysicsRigidBodyAPI", "PhysicsMassAPI"]
                    )
                    {
                        point3f physics:centerOfMass = (0.000931, 0.000346, 0.15082)
                        float3 physics:diagonalInertia = (0.02555828, 0.047013924, 0.0591438)
                        float physics:mass = 6.78
                        quatf physics:principalAxes = (0.72554046, -0.0006994608, 0.6881779, -0.0013253787)

                        over "logo_link" (
                            prepend apiSchemas = ["PhysicsRigidBodyAPI", "PhysicsMassAPI"]
                        )
                        {
                            point3f physics:centerOfMass = (0, 0, 0)
                            float3 physics:diagonalInertia = (1e-7, 1e-7, 1e-7)
                            float physics:mass = 0.001
                            quatf physics:principalAxes = (1, 0, 0, 0)
                        }

                        over "head_link" (
                            prepend apiSchemas = ["PhysicsRigidBodyAPI", "PhysicsMassAPI"]
                        )
                        {
                            point3f physics:centerOfMass = (0.005267, 0.000299, 0.449869)
                            float3 physics:diagonalInertia = (0.0018057885, 0.0040871073, 0.004185278)
                            float physics:mass = 1.036
                            quatf physics:principalAxes = (0.51341033, 0.5016372, 0.49878, 0.4857864)
                        }

                        over "left_shoulder_pitch_link" (
                            prepend apiSchemas = ["PhysicsRigidBodyAPI", "PhysicsMassAPI"]
                        )
                        {
                            point3f physics:centerOfMass = (0, 0.035892, -0.011628)
                            float3 physics:diagonalInertia = (0.0004063939, 0.0004328424, 0.00046586368)
                            float physics:mass = 0.718
                            quatf physics:principalAxes = (0.4916483, 0.23184995, 0.47319868, 0.6932608)

                            over "left_shoulder_roll_link" (
                                prepend apiSchemas = ["PhysicsRigidBodyAPI", "PhysicsMassAPI"]
                            )
                            {
                                point3f physics:centerOfMass = (-0.000227, 0.00727, -0.063243)
                                float3 physics:diagonalInertia = (0.00038897747, 0.0006180114, 0.00069131114)
                                float physics:mass = 0.643
                                quatf physics:principalAxes = (0.49001202, 0.49084023, 0.51776165, 0.5008862)

                                over "left_shoulder_yaw_link" (
                                    prepend apiSchemas = ["PhysicsRigidBodyAPI", "PhysicsMassAPI"]
                                )
                                {
                                    point3f physics:centerOfMass = (0.010773, -0.002949, -0.072009)
                                    float3 physics:diagonalInertia = (0.00040066076, 0.001032166, 0.0010618733)
                                    float physics:mass = 0.734
                                    quatf physics:principalAxes = (0.4176533, 0.45883054, 0.55410075, 0.55498886)

                                    over "left_elbow_link" (
                                        prepend apiSchemas = ["PhysicsRigidBodyAPI", "PhysicsMassAPI"]
                                    )
                                    {
                                        point3f physics:centerOfMass = (0.064956, 0.004454, -0.010062)
                                        float3 physics:diagonalInertia = (0.00025935346, 0.00042161156, 0.00044303498)
                                        float physics:mass = 0.6
                                        quatf physics:principalAxes = (-0.6580238, 0.72426236, -0.10814794, -0.1753646)

                                        over "left_wrist_roll_link" (
                                            prepend apiSchemas = ["PhysicsRigidBodyAPI", "PhysicsMassAPI"]
                                        )
                                        {
                                            point3f physics:centerOfMass = (0.017139448, 0.00053759094, 4.8864e-7)
                                            float3 physics:diagonalInertia = (0.00003577985, 0.000049664577, 0.00005482107)
                                            float physics:mass = 0.08544498
                                            quatf physics:principalAxes = (0.00040522843, 0.8133457, 0.5817805, -0.00030537136)

                                            over "left_wrist_pitch_link" (
                                                prepend apiSchemas = ["PhysicsRigidBodyAPI", "PhysicsMassAPI"]
                                            )
                                            {
                                                point3f physics:centerOfMass = (0.025491504, -0.0005404251, -0.0005414385)
                                                float3 physics:diagonalInertia = (0.0002556689, 0.00071607874, 0.00071649475)
                                                float physics:mass = 0.684
                                                quatf physics:principalAxes = (-0.68930286, 0.724353, 0.0003539481, 0.013197154)

                                                over "left_wrist_yaw_link" (
                                                    prepend apiSchemas = ["PhysicsRigidBodyAPI", "PhysicsMassAPI"]
                                                )
                                                {
                                                    point3f physics:centerOfMass = (0.022003816, 0.000494851, 0.0005386112)
                                                    float3 physics:diagonalInertia = (0.000037568436, 0.00005098067, 0.0000597564)
                                                    float physics:mass = 0.08457647
                                                    quatf physics:principalAxes = (0.41463053, 0.3872417, 0.58622634, 0.57832867)

                                                    over "left_rubber_hand" (
                                                        prepend apiSchemas = ["PhysicsRigidBodyAPI", "PhysicsMassAPI"]
                                                    )
                                                    {
                                                        point3f physics:centerOfMass = (0.053613108, -0.0029590523, 0.002154131)
                                                        float3 physics:diagonalInertia = (0.00009399108, 0.0002188241, 0.00028848607)
                                                        float physics:mass = 0.17
                                                        quatf physics:principalAxes = (-0.68838847, 0.7190292, -0.07263266, -0.061990503)
                                                    }
                                                }
                                            }
                                        }
                                    }
                                }

                                over "cylinder" (
                                    prepend apiSchemas = ["NewtonCollisionAPI"]
                                )
                                {
                                }
                            }

                            over "cylinder" (
                                prepend apiSchemas = ["NewtonCollisionAPI"]
                            )
                            {
                            }
                        }

                        over "right_shoulder_pitch_link" (
                            prepend apiSchemas = ["PhysicsRigidBodyAPI", "PhysicsMassAPI"]
                        )
                        {
                            point3f physics:centerOfMass = (0, -0.035892, -0.011628)
                            float3 physics:diagonalInertia = (0.0004063939, 0.0004328424, 0.00046586368)
                            float physics:mass = 0.718
                            quatf physics:principalAxes = (0.23184995, 0.4916483, 0.6932608, 0.47319868)

                            over "right_shoulder_roll_link" (
                                prepend apiSchemas = ["PhysicsRigidBodyAPI", "PhysicsMassAPI"]
                            )
                            {
                                point3f physics:centerOfMass = (-0.000227, -0.00727, -0.063243)
                                float3 physics:diagonalInertia = (0.00038897747, 0.0006180114, 0.00069131114)
                                float physics:mass = 0.643
                                quatf physics:principalAxes = (0.49084023, 0.49001202, 0.5008862, 0.51776165)

                                over "right_shoulder_yaw_link" (
                                    prepend apiSchemas = ["PhysicsRigidBodyAPI", "PhysicsMassAPI"]
                                )
                                {
                                    point3f physics:centerOfMass = (0.010773, 0.002949, -0.072009)
                                    float3 physics:diagonalInertia = (0.00040066076, 0.001032166, 0.0010618733)
                                    float physics:mass = 0.734
                                    quatf physics:principalAxes = (0.45883054, 0.4176533, 0.55498886, 0.55410075)

                                    over "right_elbow_link" (
                                        prepend apiSchemas = ["PhysicsRigidBodyAPI", "PhysicsMassAPI"]
                                    )
                                    {
                                        point3f physics:centerOfMass = (0.064956, -0.004454, -0.010062)
                                        float3 physics:diagonalInertia = (0.00025935346, 0.00042161156, 0.00044303498)
                                        float physics:mass = 0.6
                                        quatf physics:principalAxes = (0.72426236, -0.6580238, -0.1753646, -0.10814794)

                                        over "right_wrist_roll_link" (
                                            prepend apiSchemas = ["PhysicsRigidBodyAPI", "PhysicsMassAPI"]
                                        )
                                        {
                                            point3f physics:centerOfMass = (0.017139448, -0.00053759094, 4.8864e-7)
                                            float3 physics:diagonalInertia = (0.00003577985, 0.000049664577, 0.00005482107)
                                            float physics:mass = 0.08544498
                                            quatf physics:principalAxes = (0.00030537136, 0.5817805, 0.8133457, -0.00040522843)

                                            over "right_wrist_pitch_link" (
                                                prepend apiSchemas = ["PhysicsRigidBodyAPI", "PhysicsMassAPI"]
                                            )
                                            {
                                                point3f physics:centerOfMass = (0.025491504, 0.0005404251, -0.0005414385)
                                                float3 physics:diagonalInertia = (0.0002556689, 0.00071607874, 0.00071649475)
                                                float physics:mass = 0.684
                                                quatf physics:principalAxes = (-0.68930286, 0.724353, -0.0003539481, -0.013197154)

                                                over "right_wrist_yaw_link" (
                                                    prepend apiSchemas = ["PhysicsRigidBodyAPI", "PhysicsMassAPI"]
                                                )
                                                {
                                                    point3f physics:centerOfMass = (0.022003816, -0.000494851, 0.0005386112)
                                                    float3 physics:diagonalInertia = (0.000037568436, 0.00005098067, 0.0000597564)
                                                    float physics:mass = 0.08457647
                                                    quatf physics:principalAxes = (0.3872417, 0.41463053, 0.57832867, 0.58622634)

                                                    over "right_rubber_hand" (
                                                        prepend apiSchemas = ["PhysicsRigidBodyAPI", "PhysicsMassAPI"]
                                                    )
                                                    {
                                                        point3f physics:centerOfMass = (0.053613108, 0.0029590523, 0.002154131)
                                                        float3 physics:diagonalInertia = (0.00009399108, 0.0002188241, 0.00028848607)
                                                        float physics:mass = 0.17
                                                        quatf physics:principalAxes = (0.7190292, -0.68838847, -0.061990503, -0.07263266)
                                                    }
                                                }
                                            }
                                        }
                                    }
                                }

                                over "cylinder" (
                                    prepend apiSchemas = ["NewtonCollisionAPI"]
                                )
                                {
                                }
                            }

                            over "cylinder" (
                                prepend apiSchemas = ["NewtonCollisionAPI"]
                            )
                            {
                            }
                        }

                        over "imu_in_torso" (
                            prepend apiSchemas = ["PhysicsRigidBodyAPI", "PhysicsMassAPI"]
                        )
                        {
                        }

                        over "d435_link" (
                            prepend apiSchemas = ["PhysicsRigidBodyAPI", "PhysicsMassAPI"]
                        )
                        {
                        }

                        over "mid360_link" (
                            prepend apiSchemas = ["PhysicsRigidBodyAPI", "PhysicsMassAPI"]
                        )
                        {
                        }
                    }
                }
            }

            over "imu_in_pelvis" (
                prepend apiSchemas = ["PhysicsRigidBodyAPI", "PhysicsMassAPI"]
            )
            {
            }
        }
    }

    over "Physics"
    {
        def PhysicsRevoluteJoint "left_hip_pitch_joint" (
            prepend apiSchemas = ["PhysicsDriveAPI:angular", "PhysicsJointStateAPI:angular"]
        )
        {
            float drive:angular:physics:maxForce = 139
            uniform token physics:axis = "Y"
            custom rel physics:body0 = </g1_29dof_mode_15/Geometry/pelvis>
            custom rel physics:body1 = </g1_29dof_mode_15/Geometry/pelvis/left_hip_pitch_link>
            point3f physics:localPos0 = (0, 0.064452, -0.1027)
            point3f physics:localPos1 = (0, 0, 0)
            quatf physics:localRot0 = (1, 0, 0, 0)
            quatf physics:localRot1 = (1, 0, 0, 0)
            float physics:lowerLimit = -144.99843
            float physics:upperLimit = 165.00038
            custom float urdf:limit:effort = 139
            custom float urdf:limit:velocity = 20
        }

        def PhysicsRevoluteJoint "left_hip_roll_joint" (
            prepend apiSchemas = ["PhysicsDriveAPI:angular", "PhysicsJointStateAPI:angular"]
        )
        {
            float drive:angular:physics:maxForce = 139
            uniform token physics:axis = "X"
            custom rel physics:body0 = </g1_29dof_mode_15/Geometry/pelvis/left_hip_pitch_link>
            custom rel physics:body1 = </g1_29dof_mode_15/Geometry/pelvis/left_hip_pitch_link/left_hip_roll_link>
            point3f physics:localPos0 = (0, 0.052, -0.030465)
            point3f physics:localPos1 = (0, 0, 0)
            quatf physics:localRot0 = (0.9961787, 0, -0.08733856, 0)
            quatf physics:localRot1 = (1, 0, 0, 0)
            float physics:lowerLimit = -30.00007
            float physics:upperLimit = 170.0023
            custom float urdf:limit:effort = 139
            custom float urdf:limit:velocity = 20
        }

        def PhysicsRevoluteJoint "left_hip_yaw_joint" (
            prepend apiSchemas = ["PhysicsDriveAPI:angular", "PhysicsJointStateAPI:angular"]
        )
        {
            float drive:angular:physics:maxForce = 88
            uniform token physics:axis = "Z"
            custom rel physics:body0 = </g1_29dof_mode_15/Geometry/pelvis/left_hip_pitch_link/left_hip_roll_link>
            custom rel physics:body1 = </g1_29dof_mode_15/Geometry/pelvis/left_hip_pitch_link/left_hip_roll_link/left_hip_yaw_link>
            point3f physics:localPos0 = (0.025001, 0, -0.12412)
            point3f physics:localPos1 = (0, 0, 0)
            quatf physics:localRot0 = (1, 0, 0, 0)
            quatf physics:localRot1 = (1, 0, 0, 0)
            float physics:lowerLimit = -157.99884
            float physics:upperLimit = 157.99884
            custom float urdf:limit:effort = 88
            custom float urdf:limit:velocity = 32
        }

        def PhysicsRevoluteJoint "left_knee_joint" (
            prepend apiSchemas = ["PhysicsDriveAPI:angular", "PhysicsJointStateAPI:angular"]
        )
        {
            float drive:angular:physics:maxForce = 139
            uniform token physics:axis = "Y"
            custom rel physics:body0 = </g1_29dof_mode_15/Geometry/pelvis/left_hip_pitch_link/left_hip_roll_link/left_hip_yaw_link>
            custom rel physics:body1 = </g1_29dof_mode_15/Geometry/pelvis/left_hip_pitch_link/left_hip_roll_link/left_hip_yaw_link/left_knee_link>
            point3f physics:localPos0 = (-0.078273, 0.0021489, -0.17734)
            point3f physics:localPos1 = (0, 0, 0)
            quatf physics:localRot0 = (0.9961787, 0, 0.08733856, 0)
            quatf physics:localRot1 = (1, 0, 0, 0)
            float physics:lowerLimit = -5.000031
            float physics:upperLimit = 165.00038
            custom float urdf:limit:effort = 139
            custom float urdf:limit:velocity = 20
        }

        def PhysicsRevoluteJoint "left_ankle_pitch_joint" (
            prepend apiSchemas = ["PhysicsDriveAPI:angular", "PhysicsJointStateAPI:angular"]
        )
        {
            float drive:angular:physics:maxForce = 35
            uniform token physics:axis = "Y"
            custom rel physics:body0 = </g1_29dof_mode_15/Geometry/pelvis/left_hip_pitch_link/left_hip_roll_link/left_hip_yaw_link/left_knee_link>
            custom rel physics:body1 = </g1_29dof_mode_15/Geometry/pelvis/left_hip_pitch_link/left_hip_roll_link/left_hip_yaw_link/left_knee_link/left_ankle_pitch_link>
            point3f physics:localPos0 = (0, -0.000094445, -0.30001)
            point3f physics:localPos1 = (0, 0, 0)
            quatf physics:localRot0 = (1, 0, 0, 0)
            quatf physics:localRot1 = (1, 0, 0, 0)
            float physics:lowerLimit = -50.00031
            float physics:upperLimit = 30.00007
            custom float urdf:limit:effort = 35
            custom float urdf:limit:velocity = 30
        }

        def PhysicsRevoluteJoint "left_ankle_roll_joint" (
            prepend apiSchemas = ["PhysicsDriveAPI:angular", "PhysicsJointStateAPI:angular"]
        )
        {
            float drive:angular:physics:maxForce = 35
            uniform token physics:axis = "X"
            custom rel physics:body0 = </g1_29dof_mode_15/Geometry/pelvis/left_hip_pitch_link/left_hip_roll_link/left_hip_yaw_link/left_knee_link/left_ankle_pitch_link>
            custom rel physics:body1 = </g1_29dof_mode_15/Geometry/pelvis/left_hip_pitch_link/left_hip_roll_link/left_hip_yaw_link/left_knee_link/left_ankle_pitch_link/left_ankle_roll_link>
            point3f physics:localPos0 = (0, 0, -0.017558)
            point3f physics:localPos1 = (0, 0, 0)
            quatf physics:localRot0 = (1, 0, 0, 0)
            quatf physics:localRot1 = (1, 0, 0, 0)
            float physics:lowerLimit = -15.000035
            float physics:upperLimit = 15.000035
            custom float urdf:limit:effort = 35
            custom float urdf:limit:velocity = 30
        }

        def PhysicsRevoluteJoint "right_hip_pitch_joint" (
            prepend apiSchemas = ["PhysicsDriveAPI:angular", "PhysicsJointStateAPI:angular"]
        )
        {
            float drive:angular:physics:maxForce = 139
            uniform token physics:axis = "Y"
            custom rel physics:body0 = </g1_29dof_mode_15/Geometry/pelvis>
            custom rel physics:body1 = </g1_29dof_mode_15/Geometry/pelvis/right_hip_pitch_link>
            point3f physics:localPos0 = (0, -0.064452, -0.1027)
            point3f physics:localPos1 = (0, 0, 0)
            quatf physics:localRot0 = (1, 0, 0, 0)
            quatf physics:localRot1 = (1, 0, 0, 0)
            float physics:lowerLimit = -144.99843
            float physics:upperLimit = 165.00038
            custom float urdf:limit:effort = 139
            custom float urdf:limit:velocity = 20
        }

        def PhysicsRevoluteJoint "right_hip_roll_joint" (
            prepend apiSchemas = ["PhysicsDriveAPI:angular", "PhysicsJointStateAPI:angular"]
        )
        {
            float drive:angular:physics:maxForce = 139
            uniform token physics:axis = "X"
            custom rel physics:body0 = </g1_29dof_mode_15/Geometry/pelvis/right_hip_pitch_link>
            custom rel physics:body1 = </g1_29dof_mode_15/Geometry/pelvis/right_hip_pitch_link/right_hip_roll_link>
            point3f physics:localPos0 = (0, -0.052, -0.030465)
            point3f physics:localPos1 = (0, 0, 0)
            quatf physics:localRot0 = (0.9961787, 0, -0.08733856, 0)
            quatf physics:localRot1 = (1, 0, 0, 0)
            float physics:lowerLimit = -170.0023
            float physics:upperLimit = 30.00007
            custom float urdf:limit:effort = 139
            custom float urdf:limit:velocity = 20
        }

        def PhysicsRevoluteJoint "right_hip_yaw_joint" (
            prepend apiSchemas = ["PhysicsDriveAPI:angular", "PhysicsJointStateAPI:angular"]
        )
        {
            float drive:angular:physics:maxForce = 88
            uniform token physics:axis = "Z"
            custom rel physics:body0 = </g1_29dof_mode_15/Geometry/pelvis/right_hip_pitch_link/right_hip_roll_link>
            custom rel physics:body1 = </g1_29dof_mode_15/Geometry/pelvis/right_hip_pitch_link/right_hip_roll_link/right_hip_yaw_link>
            point3f physics:localPos0 = (0.025001, 0, -0.12412)
            point3f physics:localPos1 = (0, 0, 0)
            quatf physics:localRot0 = (1, 0, 0, 0)
            quatf physics:localRot1 = (1, 0, 0, 0)
            float physics:lowerLimit = -157.99884
            float physics:upperLimit = 157.99884
            custom float urdf:limit:effort = 88
            custom float urdf:limit:velocity = 32
        }

        def PhysicsRevoluteJoint "right_knee_joint" (
            prepend apiSchemas = ["PhysicsDriveAPI:angular", "PhysicsJointStateAPI:angular"]
        )
        {
            float drive:angular:physics:maxForce = 139
            uniform token physics:axis = "Y"
            custom rel physics:body0 = </g1_29dof_mode_15/Geometry/pelvis/right_hip_pitch_link/right_hip_roll_link/right_hip_yaw_link>
            custom rel physics:body1 = </g1_29dof_mode_15/Geometry/pelvis/right_hip_pitch_link/right_hip_roll_link/right_hip_yaw_link/right_knee_link>
            point3f physics:localPos0 = (-0.078273, -0.0021489, -0.17734)
            point3f physics:localPos1 = (0, 0, 0)
            quatf physics:localRot0 = (0.9961787, 0, 0.08733856, 0)
            quatf physics:localRot1 = (1, 0, 0, 0)
            float physics:lowerLimit = -5.000031
            float physics:upperLimit = 165.00038
            custom float urdf:limit:effort = 139
            custom float urdf:limit:velocity = 20
        }

        def PhysicsRevoluteJoint "right_ankle_pitch_joint" (
            prepend apiSchemas = ["PhysicsDriveAPI:angular", "PhysicsJointStateAPI:angular"]
        )
        {
            float drive:angular:physics:maxForce = 35
            uniform token physics:axis = "Y"
            custom rel physics:body0 = </g1_29dof_mode_15/Geometry/pelvis/right_hip_pitch_link/right_hip_roll_link/right_hip_yaw_link/right_knee_link>
            custom rel physics:body1 = </g1_29dof_mode_15/Geometry/pelvis/right_hip_pitch_link/right_hip_roll_link/right_hip_yaw_link/right_knee_link/right_ankle_pitch_link>
            point3f physics:localPos0 = (0, 0.000094445, -0.30001)
            point3f physics:localPos1 = (0, 0, 0)
            quatf physics:localRot0 = (1, 0, 0, 0)
            quatf physics:localRot1 = (1, 0, 0, 0)
            float physics:lowerLimit = -50.00031
            float physics:upperLimit = 30.00007
            custom float urdf:limit:effort = 35
            custom float urdf:limit:velocity = 30
        }

        def PhysicsRevoluteJoint "right_ankle_roll_joint" (
            prepend apiSchemas = ["PhysicsDriveAPI:angular", "PhysicsJointStateAPI:angular"]
        )
        {
            float drive:angular:physics:maxForce = 35
            uniform token physics:axis = "X"
            custom rel physics:body0 = </g1_29dof_mode_15/Geometry/pelvis/right_hip_pitch_link/right_hip_roll_link/right_hip_yaw_link/right_knee_link/right_ankle_pitch_link>
            custom rel physics:body1 = </g1_29dof_mode_15/Geometry/pelvis/right_hip_pitch_link/right_hip_roll_link/right_hip_yaw_link/right_knee_link/right_ankle_pitch_link/right_ankle_roll_link>
            point3f physics:localPos0 = (0, 0, -0.017558)
            point3f physics:localPos1 = (0, 0, 0)
            quatf physics:localRot0 = (1, 0, 0, 0)
            quatf physics:localRot1 = (1, 0, 0, 0)
            float physics:lowerLimit = -15.000035
            float physics:upperLimit = 15.000035
            custom float urdf:limit:effort = 35
            custom float urdf:limit:velocity = 30
        }

        def PhysicsRevoluteJoint "waist_yaw_joint" (
            prepend apiSchemas = ["PhysicsDriveAPI:angular", "PhysicsJointStateAPI:angular"]
        )
        {
            float drive:angular:physics:maxForce = 88
            uniform token physics:axis = "Z"
            custom rel physics:body0 = </g1_29dof_mode_15/Geometry/pelvis>
            custom rel physics:body1 = </g1_29dof_mode_15/Geometry/pelvis/waist_yaw_link>
            point3f physics:localPos0 = (0, 0, 0)
            point3f physics:localPos1 = (0, 0, 0)
            quatf physics:localRot0 = (1, 0, 0, 0)
            quatf physics:localRot1 = (1, 0, 0, 0)
            float physics:lowerLimit = -150.00035
            float physics:upperLimit = 150.00035
            custom float urdf:limit:effort = 88
            custom float urdf:limit:velocity = 32
        }

        def PhysicsRevoluteJoint "waist_roll_joint" (
            prepend apiSchemas = ["PhysicsDriveAPI:angular", "PhysicsJointStateAPI:angular"]
        )
        {
            float drive:angular:physics:maxForce = 35
            uniform token physics:axis = "X"
            custom rel physics:body0 = </g1_29dof_mode_15/Geometry/pelvis/waist_yaw_link>
            custom rel physics:body1 = </g1_29dof_mode_15/Geometry/pelvis/waist_yaw_link/waist_roll_link>
            point3f physics:localPos0 = (-0.0039635, 0, 0.044)
            point3f physics:localPos1 = (0, 0, 0)
            quatf physics:localRot0 = (1, 0, 0, 0)
            quatf physics:localRot1 = (1, 0, 0, 0)
            float physics:lowerLimit = -29.793806
            float physics:upperLimit = 29.793806
            custom float urdf:limit:effort = 35
            custom float urdf:limit:velocity = 30
        }

        def PhysicsRevoluteJoint "waist_pitch_joint" (
            prepend apiSchemas = ["PhysicsDriveAPI:angular", "PhysicsJointStateAPI:angular"]
        )
        {
            float drive:angular:physics:maxForce = 35
            uniform token physics:axis = "Y"
            custom rel physics:body0 = </g1_29dof_mode_15/Geometry/pelvis/waist_yaw_link/waist_roll_link>
            custom rel physics:body1 = </g1_29dof_mode_15/Geometry/pelvis/waist_yaw_link/waist_roll_link/torso_link>
            point3f physics:localPos0 = (0, 0, 0)
            point3f physics:localPos1 = (0, 0, 0)
            quatf physics:localRot0 = (1, 0, 0, 0)
            quatf physics:localRot1 = (1, 0, 0, 0)
            float physics:lowerLimit = -29.793806
            float physics:upperLimit = 29.793806
            custom float urdf:limit:effort = 35
            custom float urdf:limit:velocity = 30
        }

        def PhysicsRevoluteJoint "left_shoulder_pitch_joint" (
            prepend apiSchemas = ["PhysicsDriveAPI:angular", "PhysicsJointStateAPI:angular"]
        )
        {
            float drive:angular:physics:maxForce = 25
            uniform token physics:axis = "Y"
            custom rel physics:body0 = </g1_29dof_mode_15/Geometry/pelvis/waist_yaw_link/waist_roll_link/torso_link>
            custom rel physics:body1 = </g1_29dof_mode_15/Geometry/pelvis/waist_yaw_link/waist_roll_link/torso_link/left_shoulder_pitch_link>
            point3f physics:localPos0 = (0.0039563, 0.10022, 0.24778)
            point3f physics:localPos1 = (0, 0, 0)
            quatf physics:localRot0 = (0.99026406, 0.1392016, 0.000013872216, -0.00009868693)
            quatf physics:localRot1 = (1, 0, 0, 0)
            float physics:lowerLimit = -176.99812
            float physics:upperLimit = 153.00266
            custom float urdf:limit:effort = 25
            custom float urdf:limit:velocity = 37
        }

        def PhysicsRevoluteJoint "left_shoulder_roll_joint" (
            prepend apiSchemas = ["PhysicsDriveAPI:angular", "PhysicsJointStateAPI:angular"]
        )
        {
            float drive:angular:physics:maxForce = 25
            uniform token physics:axis = "X"
            custom rel physics:body0 = </g1_29dof_mode_15/Geometry/pelvis/waist_yaw_link/waist_roll_link/torso_link/left_shoulder_pitch_link>
            custom rel physics:body1 = </g1_29dof_mode_15/Geometry/pelvis/waist_yaw_link/waist_roll_link/torso_link/left_shoulder_pitch_link/left_shoulder_roll_link>
            point3f physics:localPos0 = (0, 0.038, -0.013831)
            point3f physics:localPos1 = (0, 0, 0)
            quatf physics:localRot0 = (0.99026823, -0.13917194, -5.1686486e-14, 3.6774308e-13)
            quatf physics:localRot1 = (1, 0, 0, 0)
            float physics:lowerLimit = -90.997154
            float physics:upperLimit = 129.00145
            custom float urdf:limit:effort = 25
            custom float urdf:limit:velocity = 37
        }

        def PhysicsRevoluteJoint "left_shoulder_yaw_joint" (
            prepend apiSchemas = ["PhysicsDriveAPI:angular", "PhysicsJointStateAPI:angular"]
        )
        {
            float drive:angular:physics:maxForce = 25
            uniform token physics:axis = "Z"
            custom rel physics:body0 = </g1_29dof_mode_15/Geometry/pelvis/waist_yaw_link/waist_roll_link/torso_link/left_shoulder_pitch_link/left_shoulder_roll_link>
            custom rel physics:body1 = </g1_29dof_mode_15/Geometry/pelvis/waist_yaw_link/waist_roll_link/torso_link/left_shoulder_pitch_link/left_shoulder_roll_link/left_shoulder_yaw_link>
            point3f physics:localPos0 = (0, 0.00624, -0.1032)
            point3f physics:localPos1 = (0, 0, 0)
            quatf physics:localRot0 = (1, 0, 0, 0)
            quatf physics:localRot1 = (1, 0, 0, 0)
            float physics:lowerLimit = -150.00035
            float physics:upperLimit = 150.00035
            custom float urdf:limit:effort = 25
            custom float urdf:limit:velocity = 37
        }

        def PhysicsRevoluteJoint "left_elbow_joint" (
            prepend apiSchemas = ["PhysicsDriveAPI:angular", "PhysicsJointStateAPI:angular"]
        )
        {
            float drive:angular:physics:maxForce = 25
            uniform token physics:axis = "Y"
            custom rel physics:body0 = </g1_29dof_mode_15/Geometry/pelvis/waist_yaw_link/waist_roll_link/torso_link/left_shoulder_pitch_link/left_shoulder_roll_link/left_shoulder_yaw_link>
            custom rel physics:body1 = </g1_29dof_mode_15/Geometry/pelvis/waist_yaw_link/waist_roll_link/torso_link/left_shoulder_pitch_link/left_shoulder_roll_link/left_shoulder_yaw_link/left_elbow_link>
            point3f physics:localPos0 = (0.015783, 5.551115e-17, -0.080518)
            point3f physics:localPos1 = (0, 0, 0)
            quatf physics:localRot0 = (1, 0, 0, 0)
            quatf physics:localRot1 = (1, 0, 0, 0)
            float physics:lowerLimit = -60.00014
            float physics:upperLimit = 120.00028
            custom float urdf:limit:effort = 25
            custom float urdf:limit:velocity = 37
        }

        def PhysicsRevoluteJoint "left_wrist_roll_joint" (
            prepend apiSchemas = ["PhysicsDriveAPI:angular", "PhysicsJointStateAPI:angular"]
        )
        {
            float drive:angular:physics:maxForce = 25
            uniform token physics:axis = "X"
            custom rel physics:body0 = </g1_29dof_mode_15/Geometry/pelvis/waist_yaw_link/waist_roll_link/torso_link/left_shoulder_pitch_link/left_shoulder_roll_link/left_shoulder_yaw_link/left_elbow_link>
            custom rel physics:body1 = </g1_29dof_mode_15/Geometry/pelvis/waist_yaw_link/waist_roll_link/torso_link/left_shoulder_pitch_link/left_shoulder_roll_link/left_shoulder_yaw_link/left_elbow_link/left_wrist_roll_link>
            point3f physics:localPos0 = (0.1, 0.00188791, -0.01)
            point3f physics:localPos1 = (0, 0, 0)
            quatf physics:localRot0 = (1, 0, 0, 0)
            quatf physics:localRot1 = (1, 0, 0, 0)
            float physics:lowerLimit = -113
            float physics:upperLimit = 113
            custom float urdf:limit:effort = 25
            custom float urdf:limit:velocity = 37
        }

        def PhysicsRevoluteJoint "left_wrist_pitch_joint" (
            prepend apiSchemas = ["PhysicsDriveAPI:angular", "PhysicsJointStateAPI:angular"]
        )
        {
            float drive:angular:physics:maxForce = 13.4
            uniform token physics:axis = "Y"
            custom rel physics:body0 = </g1_29dof_mode_15/Geometry/pelvis/waist_yaw_link/waist_roll_link/torso_link/left_shoulder_pitch_link/left_shoulder_roll_link/left_shoulder_yaw_link/left_elbow_link/left_wrist_roll_link>
            custom rel physics:body1 = </g1_29dof_mode_15/Geometry/pelvis/waist_yaw_link/waist_roll_link/torso_link/left_shoulder_pitch_link/left_shoulder_roll_link/left_shoulder_yaw_link/left_elbow_link/left_wrist_roll_link/left_wrist_pitch_link>
            point3f physics:localPos0 = (0.038, 2.7755576e-17, 1.3877788e-17)
            point3f physics:localPos1 = (0, 0, 0)
            quatf physics:localRot0 = (1, 0, 0, 0)
            quatf physics:localRot1 = (1, 0, 0, 0)
            float physics:lowerLimit = -92.5
            float physics:upperLimit = 92.5
            custom float urdf:limit:effort = 13.4
            custom float urdf:limit:velocity = 27
        }

        def PhysicsRevoluteJoint "left_wrist_yaw_joint" (
            prepend apiSchemas = ["PhysicsDriveAPI:angular", "PhysicsJointStateAPI:angular"]
        )
        {
            float drive:angular:physics:maxForce = 13.4
            uniform token physics:axis = "Z"
            custom rel physics:body0 = </g1_29dof_mode_15/Geometry/pelvis/waist_yaw_link/waist_roll_link/torso_link/left_shoulder_pitch_link/left_shoulder_roll_link/left_shoulder_yaw_link/left_elbow_link/left_wrist_roll_link/left_wrist_pitch_link>
            custom rel physics:body1 = </g1_29dof_mode_15/Geometry/pelvis/waist_yaw_link/waist_roll_link/torso_link/left_shoulder_pitch_link/left_shoulder_roll_link/left_shoulder_yaw_link/left_elbow_link/left_wrist_roll_link/left_wrist_pitch_link/left_wrist_yaw_link>
            point3f physics:localPos0 = (0.051, -2.7755576e-17, -1.3877788e-17)
            point3f physics:localPos1 = (0, 0, 0)
            quatf physics:localRot0 = (1, 0, 0, 0)
            quatf physics:localRot1 = (1, 0, 0, 0)
            float physics:lowerLimit = -92.5
            float physics:upperLimit = 92.5
            custom float urdf:limit:effort = 13.4
            custom float urdf:limit:velocity = 27
        }

        def PhysicsRevoluteJoint "right_shoulder_pitch_joint" (
            prepend apiSchemas = ["PhysicsDriveAPI:angular", "PhysicsJointStateAPI:angular"]
        )
        {
            float drive:angular:physics:maxForce = 25
            uniform token physics:axis = "Y"
            custom rel physics:body0 = </g1_29dof_mode_15/Geometry/pelvis/waist_yaw_link/waist_roll_link/torso_link>
            custom rel physics:body1 = </g1_29dof_mode_15/Geometry/pelvis/waist_yaw_link/waist_roll_link/torso_link/right_shoulder_pitch_link>
            point3f physics:localPos0 = (0.0039563, -0.10021, 0.24778)
            point3f physics:localPos1 = (0, 0, 0)
            quatf physics:localRot0 = (0.99026406, -0.1392016, 0.000013872216, 0.00009868693)
            quatf physics:localRot1 = (1, 0, 0, 0)
            float physics:lowerLimit = -176.99812
            float physics:upperLimit = 153.00266
            custom float urdf:limit:effort = 25
            custom float urdf:limit:velocity = 37
        }

        def PhysicsRevoluteJoint "right_shoulder_roll_joint" (
            prepend apiSchemas = ["PhysicsDriveAPI:angular", "PhysicsJointStateAPI:angular"]
        )
        {
            float drive:angular:physics:maxForce = 25
            uniform token physics:axis = "X"
            custom rel physics:body0 = </g1_29dof_mode_15/Geometry/pelvis/waist_yaw_link/waist_roll_link/torso_link/right_shoulder_pitch_link>
            custom rel physics:body1 = </g1_29dof_mode_15/Geometry/pelvis/waist_yaw_link/waist_roll_link/torso_link/right_shoulder_pitch_link/right_shoulder_roll_link>
            point3f physics:localPos0 = (6.7762636e-21, -0.038, -0.013831)
            point3f physics:localPos1 = (0, 0, 0)
            quatf physics:localRot0 = (0.99026823, 0.13917194, -5.169905e-14, -3.6774135e-13)
            quatf physics:localRot1 = (1, 0, 0, 0)
            float physics:lowerLimit = -129.00145
            float physics:upperLimit = 90.997154
            custom float urdf:limit:effort = 25
            custom float urdf:limit:velocity = 37
        }

        def PhysicsRevoluteJoint "right_shoulder_yaw_joint" (
            prepend apiSchemas = ["PhysicsDriveAPI:angular", "PhysicsJointStateAPI:angular"]
        )
        {
            float drive:angular:physics:maxForce = 25
            uniform token physics:axis = "Z"
            custom rel physics:body0 = </g1_29dof_mode_15/Geometry/pelvis/waist_yaw_link/waist_roll_link/torso_link/right_shoulder_pitch_link/right_shoulder_roll_link>
            custom rel physics:body1 = </g1_29dof_mode_15/Geometry/pelvis/waist_yaw_link/waist_roll_link/torso_link/right_shoulder_pitch_link/right_shoulder_roll_link/right_shoulder_yaw_link>
            point3f physics:localPos0 = (0, -0.00624, -0.1032)
            point3f physics:localPos1 = (0, 0, 0)
            quatf physics:localRot0 = (1, 0, 0, 0)
            quatf physics:localRot1 = (1, 0, 0, 0)
            float physics:lowerLimit = -150.00035
            float physics:upperLimit = 150.00035
            custom float urdf:limit:effort = 25
            custom float urdf:limit:velocity = 37
        }

        def PhysicsRevoluteJoint "right_elbow_joint" (
            prepend apiSchemas = ["PhysicsDriveAPI:angular", "PhysicsJointStateAPI:angular"]
        )
        {
            float drive:angular:physics:maxForce = 25
            uniform token physics:axis = "Y"
            custom rel physics:body0 = </g1_29dof_mode_15/Geometry/pelvis/waist_yaw_link/waist_roll_link/torso_link/right_shoulder_pitch_link/right_shoulder_roll_link/right_shoulder_yaw_link>
            custom rel physics:body1 = </g1_29dof_mode_15/Geometry/pelvis/waist_yaw_link/waist_roll_link/torso_link/right_shoulder_pitch_link/right_shoulder_roll_link/right_shoulder_yaw_link/right_elbow_link>
            point3f physics:localPos0 = (0.015783, -2.7755576e-17, -0.080518)
            point3f physics:localPos1 = (0, 0, 0)
            quatf physics:localRot0 = (1, 0, 0, 0)
            quatf physics:localRot1 = (1, 0, 0, 0)
            float physics:lowerLimit = -60.00014
            float physics:upperLimit = 120.00028
            custom float urdf:limit:effort = 25
            custom float urdf:limit:velocity = 37
        }

        def PhysicsRevoluteJoint "right_wrist_roll_joint" (
            prepend apiSchemas = ["PhysicsDriveAPI:angular", "PhysicsJointStateAPI:angular"]
        )
        {
            float drive:angular:physics:maxForce = 25
            uniform token physics:axis = "X"
            custom rel physics:body0 = </g1_29dof_mode_15/Geometry/pelvis/waist_yaw_link/waist_roll_link/torso_link/right_shoulder_pitch_link/right_shoulder_roll_link/right_shoulder_yaw_link/right_elbow_link>
            custom rel physics:body1 = </g1_29dof_mode_15/Geometry/pelvis/waist_yaw_link/waist_roll_link/torso_link/right_shoulder_pitch_link/right_shoulder_roll_link/right_shoulder_yaw_link/right_elbow_link/right_wrist_roll_link>
            point3f physics:localPos0 = (0.1, -0.00188791, -0.01)
            point3f physics:localPos1 = (0, 0, 0)
            quatf physics:localRot0 = (1, 0, 0, 0)
            quatf physics:localRot1 = (1, 0, 0, 0)
            float physics:lowerLimit = -113
            float physics:upperLimit = 113
            custom float urdf:limit:effort = 25
            custom float urdf:limit:velocity = 37
        }

        def PhysicsRevoluteJoint "right_wrist_pitch_joint" (
            prepend apiSchemas = ["PhysicsDriveAPI:angular", "PhysicsJointStateAPI:angular"]
        )
        {
            float drive:angular:physics:maxForce = 13.4
            uniform token physics:axis = "Y"
            custom rel physics:body0 = </g1_29dof_mode_15/Geometry/pelvis/waist_yaw_link/waist_roll_link/torso_link/right_shoulder_pitch_link/right_shoulder_roll_link/right_shoulder_yaw_link/right_elbow_link/right_wrist_roll_link>
            custom rel physics:body1 = </g1_29dof_mode_15/Geometry/pelvis/waist_yaw_link/waist_roll_link/torso_link/right_shoulder_pitch_link/right_shoulder_roll_link/right_shoulder_yaw_link/right_elbow_link/right_wrist_roll_link/right_wrist_pitch_link>
            point3f physics:localPos0 = (0.038, 0, 1.3877788e-17)
            point3f physics:localPos1 = (0, 0, 0)
            quatf physics:localRot0 = (1, 0, 0, 0)
            quatf physics:localRot1 = (1, 0, 0, 0)
            float physics:lowerLimit = -92.5
            float physics:upperLimit = 92.5
            custom float urdf:limit:effort = 13.4
            custom float urdf:limit:velocity = 27
        }

        def PhysicsRevoluteJoint "right_wrist_yaw_joint" (
            prepend apiSchemas = ["PhysicsDriveAPI:angular", "PhysicsJointStateAPI:angular"]
        )
        {
            float drive:angular:physics:maxForce = 13.4
            uniform token physics:axis = "Z"
            custom rel physics:body0 = </g1_29dof_mode_15/Geometry/pelvis/waist_yaw_link/waist_roll_link/torso_link/right_shoulder_pitch_link/right_shoulder_roll_link/right_shoulder_yaw_link/right_elbow_link/right_wrist_roll_link/right_wrist_pitch_link>
            custom rel physics:body1 = </g1_29dof_mode_15/Geometry/pelvis/waist_yaw_link/waist_roll_link/torso_link/right_shoulder_pitch_link/right_shoulder_roll_link/right_shoulder_yaw_link/right_elbow_link/right_wrist_roll_link/right_wrist_pitch_link/right_wrist_yaw_link>
            point3f physics:localPos0 = (0.051, 0, 0)
            point3f physics:localPos1 = (0, 0, 0)
            quatf physics:localRot0 = (1, 0, 0, 0)
            quatf physics:localRot1 = (1, 0, 0, 0)
            float physics:lowerLimit = -92.5
            float physics:upperLimit = 92.5
            custom float urdf:limit:effort = 13.4
            custom float urdf:limit:velocity = 27
        }

        def PhysicsFixedJoint "root_joint"
        {
            custom rel physics:body0 = </g1_29dof_mode_15>
            custom rel physics:body1 = </g1_29dof_mode_15/Geometry/pelvis>
            point3f physics:localPos0 = (0, 0, 0)
            point3f physics:localPos1 = (0, 0, 0)
            quatf physics:localRot0 = (1, 0, 0, 0)
            quatf physics:localRot1 = (1, 0, 0, 0)
        }

        def PhysicsFixedJoint "pelvis_contour_joint"
        {
            custom rel physics:body0 = </g1_29dof_mode_15/Geometry/pelvis>
            custom rel physics:body1 = </g1_29dof_mode_15/Geometry/pelvis/pelvis_contour_link>
            point3f physics:localPos0 = (0, 0, 0)
            point3f physics:localPos1 = (0, 0, 0)
            quatf physics:localRot0 = (1, 0, 0, 0)
            quatf physics:localRot1 = (1, 0, 0, 0)
        }

        def PhysicsFixedJoint "logo_joint"
        {
            custom rel physics:body0 = </g1_29dof_mode_15/Geometry/pelvis/waist_yaw_link/waist_roll_link/torso_link>
            custom rel physics:body1 = </g1_29dof_mode_15/Geometry/pelvis/waist_yaw_link/waist_roll_link/torso_link/logo_link>
            point3f physics:localPos0 = (0.0039635, 0, -0.044)
            point3f physics:localPos1 = (0, 0, 0)
            quatf physics:localRot0 = (1, 0, 0, 0)
            quatf physics:localRot1 = (1, 0, 0, 0)
        }

        def PhysicsFixedJoint "head_joint"
        {
            custom rel physics:body0 = </g1_29dof_mode_15/Geometry/pelvis/waist_yaw_link/waist_roll_link/torso_link>
            custom rel physics:body1 = </g1_29dof_mode_15/Geometry/pelvis/waist_yaw_link/waist_roll_link/torso_link/head_link>
            point3f physics:localPos0 = (0.0039635, 0, -0.044)
            point3f physics:localPos1 = (0, 0, 0)
            quatf physics:localRot0 = (1, 0, 0, 0)
            quatf physics:localRot1 = (1, 0, 0, 0)
        }

        def PhysicsFixedJoint "imu_in_torso_joint"
        {
            custom rel physics:body0 = </g1_29dof_mode_15/Geometry/pelvis/waist_yaw_link/waist_roll_link/torso_link>
            custom rel physics:body1 = </g1_29dof_mode_15/Geometry/pelvis/waist_yaw_link/waist_roll_link/torso_link/imu_in_torso>
            point3f physics:localPos0 = (-0.03959, -0.00224, 0.14792)
            point3f physics:localPos1 = (0, 0, 0)
            quatf physics:localRot0 = (1, 0, 0, 0)
            quatf physics:localRot1 = (1, 0, 0, 0)
        }

        def PhysicsFixedJoint "imu_in_pelvis_joint"
        {
            custom rel physics:body0 = </g1_29dof_mode_15/Geometry/pelvis>
            custom rel physics:body1 = </g1_29dof_mode_15/Geometry/pelvis/imu_in_pelvis>
            point3f physics:localPos0 = (0.04525, 0, -0.08339)
            point3f physics:localPos1 = (0, 0, 0)
            quatf physics:localRot0 = (1, 0, 0, 0)
            quatf physics:localRot1 = (1, 0, 0, 0)
        }

        def PhysicsFixedJoint "d435_joint"
        {
            custom rel physics:body0 = </g1_29dof_mode_15/Geometry/pelvis/waist_yaw_link/waist_roll_link/torso_link>
            custom rel physics:body1 = </g1_29dof_mode_15/Geometry/pelvis/waist_yaw_link/waist_roll_link/torso_link/d435_link>
            point3f physics:localPos0 = (0.0576235, 0.01753, 0.42987)
            point3f physics:localPos1 = (0, 0, 0)
            quatf physics:localRot0 = (0.91495967, 0, 0.4035453, 0)
            quatf physics:localRot1 = (1, 0, 0, 0)
        }

        def PhysicsFixedJoint "mid360_joint"
        {
            custom rel physics:body0 = </g1_29dof_mode_15/Geometry/pelvis/waist_yaw_link/waist_roll_link/torso_link>
            custom rel physics:body1 = </g1_29dof_mode_15/Geometry/pelvis/waist_yaw_link/waist_roll_link/torso_link/mid360_link>
            point3f physics:localPos0 = (0.0002835, 0.00003, 0.41618)
            point3f physics:localPos1 = (0, 0, 0)
            quatf physics:localRot0 = (0.9997986, 0, 0.020069072, 0)
            quatf physics:localRot1 = (1, 0, 0, 0)
        }

        def PhysicsFixedJoint "left_hand_palm_joint"
        {
            custom rel physics:body0 = </g1_29dof_mode_15/Geometry/pelvis/waist_yaw_link/waist_roll_link/torso_link/left_shoulder_pitch_link/left_shoulder_roll_link/left_shoulder_yaw_link/left_elbow_link/left_wrist_roll_link/left_wrist_pitch_link/left_wrist_yaw_link>
            custom rel physics:body1 = </g1_29dof_mode_15/Geometry/pelvis/waist_yaw_link/waist_roll_link/torso_link/left_shoulder_pitch_link/left_shoulder_roll_link/left_shoulder_yaw_link/left_elbow_link/left_wrist_roll_link/left_wrist_pitch_link/left_wrist_yaw_link/left_rubber_hand>
            point3f physics:localPos0 = (0.0415, 0.003, 1.3877788e-17)
            point3f physics:localPos1 = (0, 0, 0)
            quatf physics:localRot0 = (1, 0, 0, 0)
            quatf physics:localRot1 = (1, 0, 0, 0)
        }

        def PhysicsFixedJoint "right_hand_palm_joint"
        {
            custom rel physics:body0 = </g1_29dof_mode_15/Geometry/pelvis/waist_yaw_link/waist_roll_link/torso_link/right_shoulder_pitch_link/right_shoulder_roll_link/right_shoulder_yaw_link/right_elbow_link/right_wrist_roll_link/right_wrist_pitch_link/right_wrist_yaw_link>
            custom rel physics:body1 = </g1_29dof_mode_15/Geometry/pelvis/waist_yaw_link/waist_roll_link/torso_link/right_shoulder_pitch_link/right_shoulder_roll_link/right_shoulder_yaw_link/right_elbow_link/right_wrist_roll_link/right_wrist_pitch_link/right_wrist_yaw_link/right_rubber_hand>
            point3f physics:localPos0 = (0.0415, -0.003, 1.3877788e-17)
            point3f physics:localPos1 = (0, 0, 0)
            quatf physics:localRot0 = (1, 0, 0, 0)
            quatf physics:localRot1 = (1, 0, 0, 0)
        }
    }
}

