<mujoco model="Q1_wo_hand">
  <compiler angle="radian" meshdir="../meshes/"/>
  <default>
    <joint damping="0.001" armature="0.01" frictionloss="0.1"/>
    <default class="collision">
      <geom group="0" rgba="0.2 0.7 0.2 1"/>
    </default>
    <geom condim='4' contype="1" conaffinity="15" solref='0.001 2' friction='1 0 0'/>
  </default>
  <asset>
    <mesh name="pelvis_link" file="pelvis_link.STL"/>
    <mesh name="L_hip_roll_link" file="L_hip_roll_link.STL"/>
    <mesh name="L_hip_yaw_link" file="L_hip_yaw_link.STL"/>
    <mesh name="L_hip_pitch_link" file="L_hip_pitch_link.STL"/>
    <mesh name="L_knee_link" file="L_knee_link.STL"/>
    <mesh name="L_ankle_pitch_link" file="L_ankle_pitch_link.STL"/>
    <mesh name="L_ankle_roll_link" file="L_ankle_roll_link.STL"/>
    <mesh name="R_hip_roll_link" file="R_hip_roll_link.STL"/>
    <mesh name="R_hip_yaw_link" file="R_hip_yaw_link.STL"/>
    <mesh name="R_hip_pitch_link" file="R_hip_pitch_link.STL"/>
    <mesh name="R_knee_link" file="R_knee_link.STL"/>
    <mesh name="R_ankle_pitch_link" file="R_ankle_pitch_link.STL"/>
    <mesh name="R_ankle_roll_link" file="R_ankle_roll_link.STL"/>
    <mesh name="torso_link" file="torso_link.STL"/>
    <mesh name="L_shoulder_pitch_link" file="L_shoulder_pitch_link.STL"/>
    <mesh name="L_shoulder_roll_link" file="L_shoulder_roll_link.STL"/>
    <mesh name="L_shoulder_yaw_link" file="L_shoulder_yaw_link.STL"/>
    <mesh name="L_elbow_link" file="L_elbow_link.STL"/>
    <mesh name="L_forearm_yaw_link" file="L_forearm_yaw_link.STL"/>
    <mesh name="L_wrist_roll_link" file="L_wrist_roll_link.STL"/>
    <mesh name="L_wrist_pitch_link" file="L_wrist_pitch_link.STL"/>
    <mesh name="R_shoulder_pitch_link" file="R_shoulder_pitch_link.STL"/>
    <mesh name="R_shoulder_roll_link" file="R_shoulder_roll_link.STL"/>
    <mesh name="R_shoulder_yaw_link" file="R_shoulder_yaw_link.STL"/>
    <mesh name="R_elbow_link" file="R_elbow_link.STL"/>
    <mesh name="R_forearm_yaw_link" file="R_forearm_yaw_link.STL"/>
    <mesh name="R_wrist_roll_link" file="R_wrist_roll_link.STL"/>
    <mesh name="R_wrist_pitch_link" file="R_wrist_pitch_link.STL"/>
    <mesh name="head_yaw_link" file="head_yaw_link.STL"/>
    <mesh name="head_pitch_link" file="head_pitch_link.STL"/>
  </asset>

  <worldbody>
    <body name="pelvis_link" pos="0 0 0.9968">
      <inertial pos="-0.072571 3.48e-05 -0.055339" quat="0.427329 0.427494 -0.563171 0.563451" mass="8.1798" diaginertia="0.123181 0.103859 0.039797"/>
      <joint name="floating_base_joint" type="free" limited="false" actuatorfrclimited="false"/>
      <geom type="mesh" contype="0" conaffinity="0" group="1" density="0" rgba="0.79216 0.81961 0.93333 1" mesh="pelvis_link"/>
      <geom size="0.04 0.175 0.05" pos="-0.1 0 -0.05" type="box" rgba="0.79216 0.81961 0.93333 1"/>
      <site name="imu" size="0.01" pos="0 0.03 0.2"/>
      <body name="L_hip_roll_link" pos="0.0154 0.125 -0.062997">
        <inertial pos="-0.021809 2.71e-05 0.0049398" quat="-0.00147974 0.685188 -0.00133567 0.728364" mass="1.6267" diaginertia="0.00365822 0.00293049 0.00199039"/>
        <joint name="L_hip_roll_joint" pos="0 0 0" axis="1 0 0" range="-0.2 0.83" actuatorfrcrange="-130 130"/>
        <geom type="mesh" contype="0" conaffinity="0" group="1" density="0" rgba="0.79216 0.81961 0.93333 1" mesh="L_hip_roll_link"/>
        <geom size="0.025 0.0085" type="cylinder" rgba="0.79216 0.81961 0.93333 1"/>
        <body name="L_hip_yaw_link">
          <inertial pos="-0.0005026 -0.0012996 -0.127531" quat="0.706579 -0.0150269 -0.00857499 0.707423" mass="3.6555" diaginertia="0.0142824 0.0121041 0.00825861"/>
          <joint name="L_hip_yaw_joint" pos="0 0 0" axis="0 0 1" range="-0.78 0.78" actuatorfrcrange="-55 55"/>
          <geom type="mesh" contype="0" conaffinity="0" group="1" density="0" rgba="0.79216 0.81961 0.93333 1" mesh="L_hip_yaw_link"/>
          <geom size="0.025 0.02" pos="0 0 -0.14" quat="0.707107 0.707107 0 0" type="cylinder" rgba="0.79216 0.81961 0.93333 1"/>
          <body name="L_hip_pitch_link" pos="0 0 -0.14">
            <inertial pos="0.0103597 0.0011742 -0.135987" quat="0.99972 -0.000456049 -0.0185207 -0.0146979" mass="2.09124" diaginertia="0.0346407 0.0332836 0.00887344"/>
            <joint name="L_hip_pitch_joint" pos="0 0 0" axis="0 1 0" range="-0.89 1.64" actuatorfrcrange="-130 130"/>
            <geom type="mesh" contype="0" conaffinity="0" group="1" density="0" rgba="0.79216 0.81961 0.93333 1" mesh="L_hip_pitch_link"/>
            <geom size="0.025 0.045" pos="0 0 -0.12" type="cylinder" rgba="0.79216 0.81961 0.93333 1"/>
            <body name="L_knee_link" pos="0 0 -0.28502">
              <inertial pos="-0.0003397 0.0004209 -0.127168" quat="0.711774 0.0114952 0.0102471 0.702239" mass="7.50021" diaginertia="0.131416 0.126317 0.0154493"/>
              <joint name="L_knee_joint" pos="0 0 0" axis="0 1 0" range="-0.1 2.3" actuatorfrcrange="-130 130"/>
              <geom type="mesh" contype="0" conaffinity="0" group="1" density="0" rgba="0.79216 0.81961 0.93333 1" mesh="L_knee_link"/>
              <geom size="0.025 0.05" pos="0 0 -0.19" type="cylinder" rgba="0.79216 0.81961 0.93333 1"/>
              <geom size="0.025 0.05" pos="0 0 -0.35" type="cylinder" rgba="0.79216 0.81961 0.93333 1"/>
              <geom size="0.025 0.05" quat="0.707107 0.707107 0 0" type="cylinder" rgba="0.79216 0.81961 0.93333 1"/>
              <body name="L_ankle_pitch_link" pos="0 0 -0.452">
                <inertial pos="-5.11e-05 0 -0.002907" quat="0.707107 0 0 0.707107" mass="0.046" diaginertia="3.9073e-06 3.5529e-06 3.3922e-06"/>
                <joint name="L_ankle_pitch_joint" pos="0 0 0" axis="0 1 0" range="-0.52 0.87" actuatorfrcrange="-66 66"/>
                <geom type="mesh" contype="0" conaffinity="0" group="1" density="0" rgba="0.64706 0.61961 0.58824 1" mesh="L_ankle_pitch_link"/>
                <geom size="0.001 0.0005" type="cylinder" rgba="0.64706 0.61961 0.58824 1"/>
                <body name="L_ankle_roll_link">
                  <inertial pos="0.031127 1.94e-05 -0.03235" quat="-0.000446724 0.749856 -0.000747754 0.661601" mass="0.96277" diaginertia="0.00584802 0.0056095 0.000716878"/>
                  <joint name="L_ankle_roll_joint" pos="0 0 0" axis="1 0 0" range="-0.4363 0.4363" actuatorfrcrange="-66 66"/>
                  <geom type="mesh" contype="0" conaffinity="0" group="1" density="0" rgba="0.79216 0.81961 0.93333 1" mesh="L_ankle_roll_link"/>
                  <geom size="0.005" pos="-0.072 0.029 -0.0517" rgba="0.79216 0.81961 0.93333 1"/>
                  <geom size="0.005" pos="-0.072 -0.029 -0.0517" rgba="0.79216 0.81961 0.93333 1"/>
                  <geom size="0.005" pos="-0.047 0.039 -0.0517" rgba="0.79216 0.81961 0.93333 1"/>
                  <geom size="0.005" pos="-0.047 -0.039 -0.0517" rgba="0.79216 0.81961 0.93333 1"/>
                  <geom size="0.005" pos="-0.079 0 -0.0517" rgba="0.79216 0.81961 0.93333 1"/>
                  <geom size="0.005" pos="0.103 0.042 -0.0517" rgba="0.79216 0.81961 0.93333 1"/>
                  <geom size="0.005" pos="0.103 -0.042 -0.0517" rgba="0.79216 0.81961 0.93333 1"/>
                  <geom size="0.005" pos="0.158 0.034 -0.0517" rgba="0.79216 0.81961 0.93333 1"/>
                  <geom size="0.005" pos="0.158 -0.034 -0.0517" rgba="0.79216 0.81961 0.93333 1"/>
                  <geom size="0.005" pos="0.183 0 -0.0517" rgba="0.79216 0.81961 0.93333 1"/>
                </body>
              </body>
            </body>
          </body>
        </body>
      </body>
      <body name="R_hip_roll_link" pos="0.0154 -0.125 -0.062997">
        <inertial pos="-0.021809 -2.71e-05 0.0049398" quat="0.00147974 0.685188 0.00133567 0.728364" mass="1.6267" diaginertia="0.00365822 0.00293049 0.00199039"/>
        <joint name="R_hip_roll_joint" pos="0 0 0" axis="1 0 0" range="-0.83 0.2" actuatorfrcrange="-130 130"/>
        <geom type="mesh" contype="0" conaffinity="0" group="1" density="0" rgba="0.79216 0.81961 0.93333 1" mesh="R_hip_roll_link"/>
        <geom size="0.025 0.0085" type="cylinder" rgba="0.79216 0.81961 0.93333 1"/>
        <body name="R_hip_yaw_link">
          <inertial pos="-0.0005022 0.0012999 -0.127531" quat="0.707423 -0.00857104 -0.0150113 0.706579" mass="3.65546" diaginertia="0.0142822 0.0121042 0.00825852"/>
          <joint name="R_hip_yaw_joint" pos="0 0 0" axis="0 0 1" range="-0.78 0.78" actuatorfrcrange="-55 55"/>
          <geom type="mesh" contype="0" conaffinity="0" group="1" density="0" rgba="0.79216 0.81961 0.93333 1" mesh="R_hip_yaw_link"/>
          <geom size="0.025 0.02" pos="0 0 -0.14" quat="0.707107 0.707107 0 0" type="cylinder" rgba="0.79216 0.81961 0.93333 1"/>
          <body name="R_hip_pitch_link" pos="0 0 -0.14">
            <inertial pos="0.0103759 -0.0011406 -0.135926" quat="0.999737 0.00046452 -0.0184164 0.0136618" mass="2.09223" diaginertia="0.0346458 0.0332859 0.00887523"/>
            <joint name="R_hip_pitch_joint" pos="0 0 0" axis="0 1 0" range="-0.89 1.64" actuatorfrcrange="-130 130"/>
            <geom type="mesh" contype="0" conaffinity="0" group="1" density="0" rgba="0.79216 0.81961 0.93333 1" mesh="R_hip_pitch_link"/>
            <geom size="0.025 0.045" pos="0 0 -0.12" type="cylinder" rgba="0.79216 0.81961 0.93333 1"/>
            <body name="R_knee_link" pos="0 0 -0.28502">
              <inertial pos="-0.0003539 -0.0004116 -0.127174" quat="0.702392 0.0102481 0.0114683 0.711624" mass="7.50218" diaginertia="0.131434 0.126331 0.0154608"/>
              <joint name="R_knee_joint" pos="0 0 0" axis="0 1 0" range="-0.1 2.3" actuatorfrcrange="-130 130"/>
              <geom type="mesh" contype="0" conaffinity="0" group="1" density="0" rgba="0.79216 0.81961 0.93333 1" mesh="R_knee_link"/>
              <geom size="0.025 0.05" pos="0 0 -0.19" type="cylinder" rgba="0.79216 0.81961 0.93333 1"/>
              <geom size="0.025 0.05" pos="0 0 -0.35" type="cylinder" rgba="0.79216 0.81961 0.93333 1"/>
              <geom size="0.025 0.05" quat="0.707107 0.707107 0 0" type="cylinder" rgba="0.79216 0.81961 0.93333 1"/>
              <body name="R_ankle_pitch_link" pos="0 0 -0.452">
                <inertial pos="-5.1137e-05 0 -0.002907" quat="0.707107 0 0 0.707107" mass="0.046143" diaginertia="3.9072e-06 3.5529e-06 3.3922e-06"/>
                <joint name="R_ankle_pitch_joint" pos="0 0 0" axis="0 1 0" range="-0.52 0.87" actuatorfrcrange="-66 66"/>
                <geom type="mesh" contype="0" conaffinity="0" group="1" density="0" rgba="0.79216 0.81961 0.93333 1" mesh="R_ankle_pitch_link"/>
                <geom size="0.001 0.0005" type="cylinder" rgba="0.79216 0.81961 0.93333 1"/>
                <body name="R_ankle_roll_link">
                  <inertial pos="0.031113 -1.04e-05 -0.032346" quat="0.000459898 0.749836 0.000841181 0.661623" mass="0.96254" diaginertia="0.00584765 0.0056094 0.000716553"/>
                  <joint name="R_ankle_roll_joint" pos="0 0 0" axis="1 0 0" range="-0.4363 0.4363" actuatorfrcrange="-66 66"/>
                  <geom type="mesh" contype="0" conaffinity="0" group="1" density="0" rgba="0.79216 0.81961 0.93333 1" mesh="R_ankle_roll_link"/>
                  <geom size="0.005" pos="-0.072 0.029 -0.0517" rgba="0.79216 0.81961 0.93333 1"/>
                  <geom size="0.005" pos="-0.072 -0.029 -0.0517" rgba="0.79216 0.81961 0.93333 1"/>
                  <geom size="0.005" pos="-0.047 0.039 -0.0517" rgba="0.79216 0.81961 0.93333 1"/>
                  <geom size="0.005" pos="-0.047 -0.039 -0.0517" rgba="0.79216 0.81961 0.93333 1"/>
                  <geom size="0.005" pos="-0.079 0 -0.0517" rgba="0.79216 0.81961 0.93333 1"/>
                  <geom size="0.005" pos="0.103 0.042 -0.0517" rgba="0.79216 0.81961 0.93333 1"/>
                  <geom size="0.005" pos="0.103 -0.042 -0.0517" rgba="0.79216 0.81961 0.93333 1"/>
                  <geom size="0.005" pos="0.158 0.034 -0.0517" rgba="0.79216 0.81961 0.93333 1"/>
                  <geom size="0.005" pos="0.158 -0.034 -0.0517" rgba="0.79216 0.81961 0.93333 1"/>
                  <geom size="0.005" pos="0.183 0 -0.0517" rgba="0.79216 0.81961 0.93333 1"/>
                </body>
              </body>
            </body>
          </body>
        </body>
      </body>
      <body name="torso_link">
        <inertial pos="0.0067502 -0.0038791 0.241647" quat="0.997554 -0.00823724 -0.0136537 0.0680612" mass="19.21" diaginertia="0.361456 0.338674 0.168684"/>
        <joint name="pelvis_joint" pos="0 0 0" axis="0 0 1" range="-1.04 1.04" actuatorfrcrange="-130 130"/>
        <geom type="mesh" contype="0" conaffinity="0" group="1" density="0" rgba="0.79216 0.81961 0.93333 1" mesh="torso_link"/>
        <geom size="0.125 0.08 0.185" pos="-0.01 0 0.25" type="box" rgba="0.79216 0.81961 0.93333 1"/>
        <body name="L_shoulder_pitch_link" pos="0.015442 0.22168 0.37829" quat="0.991445 0.130526 0 0">
          <inertial pos="0.0034819 -0.0052797 1.47e-05" quat="0.706437 0.707251 -0.0191228 -0.0194401" mass="1.35" diaginertia="0.00161569 0.0014304 0.00125011"/>
          <joint name="L_shoulder_pitch_joint" pos="0 0 0" axis="0 1 0" range="-1.48 1.48" actuatorfrcrange="-42 42"/>
          <geom type="mesh" contype="0" conaffinity="0" group="1" density="0" rgba="0.79216 0.81961 0.93333 1" mesh="L_shoulder_pitch_link"/>
          <geom size="0.025 0.015" quat="0.5 0.5 0.5 0.5" type="cylinder" rgba="0.79216 0.81961 0.93333 1"/>
          <body name="L_shoulder_roll_link">
            <inertial pos="0.0001178 0.0018666 -0.056296" quat="0.706855 0.0171153 0.00843154 0.707102" mass="0.55" diaginertia="0.00187871 0.00149694 0.00116175"/>
            <joint name="L_shoulder_roll_joint" pos="0 0 0" axis="1 0 0" range="-0.12 3.17" actuatorfrcrange="-42 42"/>
            <geom type="mesh" contype="0" conaffinity="0" group="1" density="0" rgba="0.79216 0.81961 0.93333 1" mesh="L_shoulder_roll_link"/>
            <geom size="0.02 0.015" pos="0 -0.001 -0.09" quat="0.991445 -0.130526 0 0" type="cylinder" rgba="0.79216 0.81961 0.93333 1"/>
            <body name="L_shoulder_yaw_link" pos="0 -0.043708 -0.2504" quat="0.991445 -0.130526 0 0">
              <inertial pos="0.0030369 -0.000691 0.048579" quat="0.99942 -0.000396665 -0.0324068 -0.0104301" mass="1.95" diaginertia="0.00591975 0.00576114 0.00160911"/>
              <joint name="L_shoulder_yaw_joint" pos="0 0 0" axis="0 0 1" range="-1.69 1.69" actuatorfrcrange="-23 23"/>
              <geom quat="0.707107 0 0 0.707107" type="mesh" contype="0" conaffinity="0" group="1" density="0" rgba="0.79216 0.81961 0.93333 1" mesh="L_shoulder_yaw_link"/>
              <geom size="0.02 0.03" pos="0 0 0.05" quat="0.707107 0 0 0.707107" type="cylinder" rgba="0.79216 0.81961 0.93333 1"/>
              <body name="L_elbow_link">
                <inertial pos="-0.0013729 0.0051926 -0.01857" quat="0.423804 0.564792 0.429118 0.563256" mass="0.25" diaginertia="0.00058212 0.000497093 0.000311188"/>
                <joint name="L_elbow_joint" pos="0 0 0" axis="0 1 0" range="-1.95 0.87" actuatorfrcrange="-23 23"/>
                <geom quat="0.707107 0 0 0.707107" type="mesh" contype="0" conaffinity="0" group="1" density="0" rgba="0.79216 0.81961 0.93333 1" mesh="L_elbow_link"/>
                <geom size="0.02 0.015" pos="0 0 -0.02" quat="0.707107 0 0 0.707107" type="cylinder" rgba="0.79216 0.81961 0.93333 1"/>
                <body name="L_forearm_yaw_link" pos="0 0 -0.211">
                  <inertial pos="0.0014016 0.0001246 0.09169" quat="0.714403 -0.0130686 -0.00952772 0.699548" mass="1.05" diaginertia="0.0018221 0.00166357 0.000734625"/>
                  <joint name="L_forearm_yaw_joint" pos="0 0 0" axis="0 0 1" range="-1.53 1.53" actuatorfrcrange="-8.3 8.3"/>
                  <geom type="mesh" contype="0" conaffinity="0" group="1" density="0" rgba="0.79216 0.81961 0.93333 1" mesh="L_forearm_yaw_link"/>
                  <geom size="0.025 0.015" pos="0 0 0.082" type="cylinder" rgba="0.79216 0.81961 0.93333 1"/>
                  <body name="L_wrist_roll_link">
                    <inertial pos="0 -0.0047393 -2.85e-05" quat="0.501848 0.498145 -0.498145 0.501848" mass="0.25" diaginertia="8.30015e-05 8.23e-05 5.59985e-05"/>
                    <joint name="L_wrist_roll_joint" pos="0 0 0" axis="1 0 0" range="-2.3 1.39" actuatorfrcrange="-8.3 8.3"/>
                    <geom type="mesh" contype="0" conaffinity="0" group="1" density="0" rgba="0.79216 0.81961 0.93333 1" mesh="L_wrist_roll_link"/>
                    <geom size="0.015 0.005" quat="0.707107 0 0.707107 0" type="cylinder" rgba="0.79216 0.81961 0.93333 1"/>
                    <body name="L_wrist_pitch_link">
                      <inertial pos="8.81e-05 0.0081922 -0.051309" quat="0.937586 -0.247077 -0.0627179 -0.236544" mass="0.16" diaginertia="0.000145347 0.000144694 4.01586e-05"/>
                      <joint name="L_wrist_pitch_joint" pos="0 0 0" axis="0 1 0" range="-1.78 1.67" actuatorfrcrange="-8.3 8.3"/>
                      <geom type="mesh" contype="0" conaffinity="0" group="1" density="0" rgba="0.79216 0.81961 0.93333 1" mesh="L_wrist_pitch_link"/>
                      <geom size="0.03 0.015 0.09" pos="0 0 -0.16" type="box" rgba="0.79216 0.81961 0.93333 1"/>
                    </body>
                  </body>
                </body>
              </body>
            </body>
          </body>
        </body>
        <body name="R_shoulder_pitch_link" pos="0.015442 -0.22168 0.37829" quat="0.991445 -0.130526 0 0">
          <inertial pos="0.003482 0.0052769 1.44e-05" quat="0.707267 0.706421 0.0196245 0.0189276" mass="1.35" diaginertia="0.00161579 0.0014303 0.00125011"/>
          <joint name="R_shoulder_pitch_joint" pos="0 0 0" axis="0 1 0" range="-1.48 1.48" actuatorfrcrange="-42 42"/>
          <geom type="mesh" contype="0" conaffinity="0" group="1" density="0" rgba="0.79216 0.81961 0.93333 1" mesh="R_shoulder_pitch_link"/>
          <geom size="0.025 0.015" quat="0.5 0.5 0.5 0.5" type="cylinder" rgba="0.79216 0.81961 0.93333 1"/>
          <body name="R_shoulder_roll_link">
            <inertial pos="0.00012 -0.0018541 -0.0563" quat="0.707287 0.00842865 0.0171107 0.70667" mass="0.55" diaginertia="0.00187891 0.00149704 0.00116185"/>
            <joint name="R_shoulder_roll_joint" pos="0 0 0" axis="1 0 0" range="-3.17 0.12" actuatorfrcrange="-42 42"/>
            <geom type="mesh" contype="0" conaffinity="0" group="1" density="0" rgba="0.79216 0.81961 0.93333 1" mesh="R_shoulder_roll_link"/>
            <geom size="0.02 0.015" pos="0 -0.001 -0.09" quat="0.991445 -0.130526 0 0" type="cylinder" rgba="0.79216 0.81961 0.93333 1"/>
            <body name="R_shoulder_yaw_link" pos="0 0.043708 -0.2504" quat="0.991445 0.130526 0 0">
              <inertial pos="0.0029659 0.0006795 0.04866" quat="0.999412 0.000350697 -0.0324643 0.0110351" mass="1.95" diaginertia="0.00592012 0.00576173 0.00160934"/>
              <joint name="R_shoulder_yaw_joint" pos="0 0 0" axis="0 0 1" range="-1.69 1.69" actuatorfrcrange="-23 23"/>
              <geom quat="0.707107 0 0 -0.707107" type="mesh" contype="0" conaffinity="0" group="1" density="0" rgba="0.79216 0.81961 0.93333 1" mesh="R_shoulder_yaw_link"/>
              <geom size="0.02 0.03" pos="0 0 0.05" quat="0.707107 0 0 0.707107" type="cylinder" rgba="0.79216 0.81961 0.93333 1"/>
              <body name="R_elbow_link">
                <inertial pos="-0.0013805 -0.0051935 -0.018572" quat="0.563322 0.429032 0.564858 0.423716" mass="0.25" diaginertia="0.000582027 0.000497085 0.000311188"/>
                <joint name="R_elbow_joint" pos="0 0 0" axis="0 1 0" range="-0.87 1.95" actuatorfrcrange="-23 23"/>
                <geom quat="0.707107 0 0 -0.707107" type="mesh" contype="0" conaffinity="0" group="1" density="0" rgba="0.79216 0.81961 0.93333 1" mesh="R_elbow_link"/>
                <geom size="0.02 0.015" pos="0 0 -0.02" quat="0.707107 0 0 0.707107" type="cylinder" rgba="0.79216 0.81961 0.93333 1"/>
                <body name="R_forearm_yaw_link" pos="0 0 -0.211">
                  <inertial pos="0.0014 -0.0001237 0.09169" quat="0.699552 -0.00953096 -0.0130726 0.714398" mass="1.05" diaginertia="0.001822 0.00166338 0.000734725"/>
                  <joint name="R_forearm_yaw_joint" pos="0 0 0" axis="0 0 1" range="-1.53 1.53" actuatorfrcrange="-8.3 8.3"/>
                  <geom type="mesh" contype="0" conaffinity="0" group="1" density="0" rgba="0.79216 0.81961 0.93333 1" mesh="R_forearm_yaw_link"/>
                  <geom size="0.025 0.015" pos="0 0 0.082" type="cylinder" rgba="0.79216 0.81961 0.93333 1"/>
                  <body name="R_wrist_roll_link">
                    <inertial pos="0 0.0047393 -2.85e-05" quat="0.498145 0.501848 -0.501848 0.498145" mass="0.25" diaginertia="8.30015e-05 8.23e-05 5.59985e-05"/>
                    <joint name="R_wrist_roll_joint" pos="0 0 0" axis="1 0 0" range="-1.39 2.3" actuatorfrcrange="-8.3 8.3"/>
                    <geom type="mesh" contype="0" conaffinity="0" group="1" density="0" rgba="0.79216 0.81961 0.93333 1" mesh="R_wrist_roll_link"/>
                    <geom size="0.015 0.005" quat="0.707107 0 0.707107 0" type="cylinder" rgba="0.79216 0.81961 0.93333 1"/>
                    <body name="R_wrist_pitch_link">
                      <inertial pos="8.81e-05 -0.0081922 -0.051309" quat="0.937586 0.247077 -0.0627179 0.236544" mass="0.16" diaginertia="0.000145347 0.000144694 4.01586e-05"/>
                      <joint name="R_wrist_pitch_joint" pos="0 0 0" axis="0 1 0" range="-1.78 1.67" actuatorfrcrange="-8.3 8.3"/>
                      <geom type="mesh" contype="0" conaffinity="0" group="1" density="0" rgba="0.79216 0.81961 0.93333 1" mesh="R_wrist_pitch_link"/>
                      <geom size="0.03 0.015 0.09" pos="0 0 -0.16" type="box" rgba="0.79216 0.81961 0.93333 1"/>
                    </body>
                  </body>
                </body>
              </body>
            </body>
          </body>
        </body>
        <body name="head_yaw_link" pos="0.026942 0 0.61493">
          <inertial pos="9.42e-05 -0.0015802 -0.0048308" quat="0.708141 0.70596 -0.00896168 0.00879997" mass="0.8" diaginertia="0.00237972 0.0023519 0.000501882"/>
          <joint name="head_yaw_joint" pos="0 0 0" axis="0 0 1" range="-1.57 1.57" actuatorfrcrange="-2.52 2.52"/>
          <geom type="mesh" contype="0" conaffinity="0" group="1" density="0" rgba="0.79216 0.81961 0.93333 1" mesh="head_yaw_link"/>
          <geom type="mesh" rgba="0.79216 0.81961 0.93333 1" mesh="head_yaw_link"/>
          <body name="head_pitch_link">
            <inertial pos="0.021366 0.0020556 0.027951" quat="0.195821 0.788624 0.279468 0.511492" mass="0.72904" diaginertia="0.00447361 0.00437721 0.00318018"/>
            <joint name="head_pitch_joint" pos="0 0 0" axis="0 1 0" range="-0.38 0.33" actuatorfrcrange="-2.52 2.52"/>
            <geom type="mesh" contype="0" conaffinity="0" group="1" density="0" rgba="0.79216 0.81961 0.93333 1" mesh="head_pitch_link"/>
            <geom type="mesh" rgba="0.79216 0.81961 0.93333 1" mesh="head_pitch_link"/>
          </body>
        </body>
      </body>
    </body>
  </worldbody>

  <actuator>
    <motor name="L_hip_roll_joint" joint="L_hip_roll_joint" ctrlrange="-130 130"/>
    <motor name="L_hip_yaw_joint" joint="L_hip_yaw_joint" ctrlrange="-55 55"/>
    <motor name="L_hip_pitch_joint" joint="L_hip_pitch_joint" ctrlrange="-130 130"/>
    <motor name="L_knee_joint" joint="L_knee_joint" ctrlrange="-130 130"/>
    <motor name="L_ankle_pitch_joint" joint="L_ankle_pitch_joint" ctrlrange="-66 66"/>
    <motor name="L_ankle_roll_joint" joint="L_ankle_roll_joint" ctrlrange="-66 66"/>

    <motor name="R_hip_roll_joint" joint="R_hip_roll_joint" ctrlrange="-130 130"/>
    <motor name="R_hip_yaw_joint" joint="R_hip_yaw_joint" ctrlrange="-55 55"/>
    <motor name="R_hip_pitch_joint" joint="R_hip_pitch_joint" ctrlrange="-130 130"/>
    <motor name="R_knee_joint" joint="R_knee_joint" ctrlrange="-130 130"/>
    <motor name="R_ankle_pitch_joint" joint="R_ankle_pitch_joint" ctrlrange="-66 66"/>
    <motor name="R_ankle_roll_joint" joint="R_ankle_roll_joint" ctrlrange="-66 66"/>

    <motor name="pelvis_joint" joint="pelvis_joint" ctrlrange="-130 130"/>

    <motor name="L_shoulder_pitch_joint" joint="L_shoulder_pitch_joint" ctrlrange="-42 42"/>
    <motor name="L_shoulder_roll_joint" joint="L_shoulder_roll_joint" ctrlrange="-42 42"/>
    <motor name="L_shoulder_yaw_joint" joint="L_shoulder_yaw_joint" ctrlrange="-23 23"/>
    <motor name="L_elbow_joint" joint="L_elbow_joint" ctrlrange="-23 23"/>
    <motor name="L_forearm_yaw_joint" joint="L_forearm_yaw_joint" ctrlrange="-8.3 8.3"/>
    <motor name="L_wrist_roll_joint" joint="L_wrist_roll_joint" ctrlrange="-3.3 3.3"/>
    <motor name="L_wrist_pitch_joint" joint="L_wrist_pitch_joint" ctrlrange="-3.3 3.3"/>

    <motor name="R_shoulder_pitch_joint" joint="R_shoulder_pitch_joint" ctrlrange="-42 42"/>
    <motor name="R_shoulder_roll_joint" joint="R_shoulder_roll_joint" ctrlrange="-42 42"/>
    <motor name="R_shoulder_yaw_joint" joint="R_shoulder_yaw_joint" ctrlrange="-23 23"/>
    <motor name="R_elbow_joint" joint="R_elbow_joint" ctrlrange="-23 23"/>
    <motor name="R_forearm_yaw_joint" joint="R_forearm_yaw_joint" ctrlrange="-8.3 8.3"/>
    <motor name="R_wrist_roll_joint" joint="R_wrist_roll_joint" ctrlrange="-3.3 3.3"/>
    <motor name="R_wrist_pitch_joint" joint="R_wrist_pitch_joint" ctrlrange="-3.3 3.3"/>

    <motor name="head_yaw_joint" joint="head_yaw_joint" ctrlrange="-2.52 2.52"/>
    <motor name="head_pitch_joint" joint="head_pitch_joint" ctrlrange="-1.26 1.26"/>

  </actuator>

  <sensor>
    <gyro name="imu-angular-velocity" site="imu" noise="5e-4" cutoff="34.9"/>
    <accelerometer name="imu-linear-acceleration" site="imu" noise="1e-2" cutoff="157"/>
  </sensor>
  <!-- setup scene -->
  <statistic center="1.0 0.7 1.0" extent="0.8" />
  <visual>
    <headlight diffuse="0.6 0.6 0.6" ambient="0.1 0.1 0.1" specular="0.9 0.9 0.9" />
    <rgba haze="0.15 0.25 0.35 1" />
    <global azimuth="-140" elevation="-20" offwidth="2080" offheight="1170" />
  </visual>
  <asset>
    <texture type="skybox" builtin="gradient" rgb1="1 1 1" rgb2="1 1 1" width="800" height="800" />
    <texture type="2d" name="groundplane" builtin="checker" mark="edge" rgb1="1 1 1" rgb2="1 1 1" markrgb="0 0 0" width="300" height="300" />
    <material name="groundplane" texture="groundplane" texuniform="true" texrepeat="5 5" reflectance="0" />
    <texture type="skybox" builtin="gradient" rgb1=".4 .5 .6" rgb2="0 0 0" width="100" height="100" />
    <texture builtin="flat" height="1278" mark="cross" markrgb="1 1 1" name="texgeom" random="0.01" rgb1="0.8 0.6 0.4" rgb2="0.8 0.6 0.4" type="cube" width="127" />
    <texture name="texplane" builtin="checker" height="512" width="512" rgb1=".2 .3 .4" rgb2=".1 .15 .2" type="2d" />
    <material name="MatPlane" reflectance="0.5" shininess="0.01" specular="0.1" texrepeat="1 1" texture="texplane" texuniform="true" />
    <material name="geom" texture="texgeom" texuniform="true" />
  </asset>
  <worldbody>
    <geom name="floor" size="0 0 0.01" type="plane" material="groundplane" contype="1" conaffinity="0" priority="1" friction="0.6" condim="3" />
    <geom name="floor1" size="0 0 0.01" type="plane" material="groundplane" contype="0" conaffinity="0" priority="1" friction="0.6" condim="3"  group="1" />
    <light diffuse=".5 .5 .5" pos="-3 -3 5" dir="3 3 -5" castshadow="true" />
  </worldbody>
</mujoco>
