<?xml version="1.0" encoding="utf-8"?>
<robot name="Q1">
  <mujoco>
    <compiler meshdir="../meshes" discardvisual="false" />
  </mujoco>
  <!-- [CAUTION] uncomment when convert to mujoco -->
  <!-- <link name="world"></link>
  <joint name="floating_base_joint" type="floating">
    <parent link="world" />
    <child link="pelvis_link" />
  </joint> -->
<!-- pelvis -->
  <link name="pelvis_link">
    <inertial>
      <origin xyz="-0.072571 3.48E-05 -0.055339" rpy="0 0 0" />
      <mass value="8.1798" />
      <inertia ixx="0.10526" ixy="2.7E-05" ixz="-0.0050108" iyy="0.039797" iyz="1.22E-05" izz="0.12178" />
    </inertial>
    <visual>
      <origin xyz="0 0 0" rpy="0 0 0" />
      <geometry>
        <mesh filename="meshes/pelvis_link.STL" />
      </geometry>
      <material name="">
        <color rgba="0.79216 0.81961 0.93333 1" />
      </material>
    </visual>
    <collision>
      <origin xyz="-0.1 0 -0.05" rpy="0 0 0" />
      <geometry>
        <box size="0.08 0.35 0.1"/>
      </geometry>
    </collision>
  </link>
<!-- Left leg -->
  <link name="L_hip_roll_link">
    <inertial>
      <origin xyz="-0.021809 2.71E-05 0.0049398" rpy="0 0 0" />
      <mass value="1.6267" />
      <inertia ixx="0.0019966" ixy="1E-07" ixz="-0.0001016" iyy="0.0029305" iyz="-2.9E-06" izz="0.003652" />
    </inertial>
    <visual>
      <origin xyz="0 0 0" rpy="0 0 0" />
      <geometry>
        <mesh filename="meshes/L_hip_roll_link.STL" />
      </geometry>
      <material name="">
        <color rgba="0.79216 0.81961 0.93333 1" />
      </material>
    </visual>
    <collision>
      <origin xyz="0 0 0" rpy="0 0 0" />
      <geometry>
        <cylinder radius="0.025" length="0.017"/>
      </geometry>
    </collision>
  </link>
  <joint name="L_hip_roll_joint" type="revolute"><!-- EC-A10020-P2-24 -->
    <origin xyz="0.0154 0.125 -0.062997" rpy="0 0 0" />
    <parent link="pelvis_link" />
    <child link="L_hip_roll_link" />
    <axis xyz="1 0 0" />
    <limit lower="-0.2" upper="0.83" effort="130" velocity="12.88" />
  </joint>
  <link name="L_hip_yaw_link">
    <inertial>
      <origin xyz="-0.0005026 -0.0012996 -0.1275314" rpy="0 0 0" />
      <mass value="3.6555048" />
      <inertia ixx="0.0120998" ixy="-1.1E-06" ixz="0.0001283" iyy="0.0142819" iyz="-5.49E-05" izz="0.0082634" />
    </inertial>
    <visual>
      <origin xyz="0 0 0" rpy="0 0 0" />
      <geometry>
        <mesh filename="meshes/L_hip_yaw_link.STL" />
      </geometry>
      <material name="">
        <color rgba="0.79216 0.81961 0.93333 1" />
      </material>
    </visual>
    <collision>
      <origin xyz="0 0 -0.14" rpy="1.570796327 0 0" />
      <geometry>
        <cylinder radius="0.025" length="0.04"/>
      </geometry>
    </collision>
  </link>
  <joint name="L_hip_yaw_joint" type="revolute"><!-- EC-A6416-P2-25 -->
    <origin xyz="0 0 0" rpy="0 0 0" />
    <parent link="L_hip_roll_link" />
    <child link="L_hip_yaw_link" />
    <axis xyz="0 0 1" />
    <limit lower="-0.78" upper="0.78" effort="55" velocity="12.56" />
  </joint>
  <link name="L_hip_pitch_link">
    <inertial>
      <origin xyz="0.0103597 0.0011742 -0.1359873" rpy="0 0 0" />
      <mass value="2.0912352" />
      <inertia ixx="0.0346042" ixy="-3.85E-05" ixz="0.0009532" iyy="0.0332847" iyz="-3.7E-05" izz="0.0089088" />
    </inertial>
    <visual>
      <origin xyz="0 0 0" rpy="0 0 0" />
      <geometry>
        <mesh filename="meshes/L_hip_pitch_link.STL" />
      </geometry>
      <material name="">
        <color rgba="0.79216 0.81961 0.93333 1" />
      </material>
    </visual>
    <collision>
      <origin xyz="0 0 -0.12" rpy="0 0 0" />
      <geometry>
        <cylinder radius="0.025" length="0.09"/>
      </geometry>
    </collision>
  </link>
  <joint name="L_hip_pitch_joint" type="revolute"><!-- EC-A10020-P2-24 -->
    <origin xyz="0 0 -0.14" rpy="0 0 0" />
    <parent link="L_hip_yaw_link" />
    <child link="L_hip_pitch_link" />
    <axis xyz="0 1 0" />
    <limit lower="-0.89" upper="1.64" effort="130" velocity="12.88" />
  </joint>
  <link name="L_knee_link">
    <inertial>
      <origin xyz="-0.0003397 0.0004209 -0.1271680" rpy="0 0 0" />
      <mass value="7.5002071" />
      <inertia ixx="0.1262133" ixy="7.56E-05" ixz="-0.0034056" iyy="0.1314147" iyz="0.0002265" izz="0.0155545" />
    </inertial>
    <visual>
      <origin xyz="0 0 0" rpy="0 0 0" />
      <geometry>
        <mesh filename="meshes/L_knee_link.STL" />
      </geometry>
      <material name="">
        <color rgba="0.79216 0.81961 0.93333 1" />
      </material>
    </visual>
    <collision>
      <origin xyz="0 0 -0.19" rpy="0 0 0" />
      <geometry>
        <cylinder radius="0.025" length="0.1"/>
      </geometry>
    </collision>
    <collision>
      <origin xyz="0 0 -0.35" rpy="0 0 0" />
      <geometry>
        <cylinder radius="0.025" length="0.1"/>
      </geometry>
    </collision>
    <collision>
      <origin xyz="0 0 0.0" rpy="1.570796327 0 0" />
      <geometry>
        <cylinder radius="0.025" length="0.1"/>
      </geometry>
    </collision>
  </link>
  <joint name="L_knee_joint" type="revolute"><!-- EC-A10020-P2-24 -->
    <origin xyz="0 0 -0.28502" rpy="0 0 0" />
    <parent link="L_hip_pitch_link" />
    <child link="L_knee_link" />
    <axis xyz="0 1 0" />
    <limit lower="-0.1" upper="2.3" effort="130" velocity="12.88" />
  </joint>
  <link name="L_ankle_pitch_link">
    <inertial>
      <origin xyz="-5.11E-05 0 -0.002907" rpy="0 0 0" />
      <mass value="0.046" />
      <inertia ixx="3.5529E-06" ixy="0" ixz="0" iyy="3.9073E-06" iyz="0" izz="3.3922E-06" />
    </inertial>
    <visual>
      <origin xyz="0 0 0" rpy="0 0 0" />
      <geometry>
        <mesh filename="meshes/L_ankle_pitch_link.STL" />
      </geometry>
      <material name="">
        <color rgba="0.64706 0.61961 0.58824 1" />
      </material>
    </visual>
    <!-- <collision>
      <origin xyz="0 0 0" rpy="0 0 0" />
      <geometry>
        <mesh filename="meshes/L_ankle_pitch_link.STL" />
      </geometry>
    </collision> -->
    <collision>
      <origin xyz="0 0 0" rpy="0 0 0" />
      <geometry>
        <cylinder radius="0.001" length="0.001"/>
        <!-- <mesh filename="meshes/L_ankle_pitch_link.STL" /> -->
      </geometry>
    </collision>
  </link>
  <joint name="L_ankle_pitch_joint" type="revolute"><!-- EC-A8116-P1-18 -->
    <origin xyz="0 0 -0.452" rpy="0 0 0" />
    <parent link="L_knee_link" />
    <child link="L_ankle_pitch_link" />
    <axis xyz="0 1 0" />
    <limit lower="-0.52" upper="0.87" effort="66" velocity="14.66" />
  </joint>
  <link name="L_ankle_roll_link">
    <inertial>
      <origin xyz="0.031127 1.94E-05 -0.03235" rpy="0 0 0" />
      <mass value="0.96277" />
      <inertia ixx="0.0007965" ixy="1.5E-06" ixz="0.0006342" iyy="0.0056095" iyz="-6E-07" izz="0.0057684" />
    </inertial>
    <visual>
      <origin xyz="0 0 0" rpy="0 0 0" />
      <geometry>
        <mesh filename="meshes/L_ankle_roll_link.STL" />
      </geometry>
      <material name="">
        <color rgba="0.79216 0.81961 0.93333 1" />
      </material>
    </visual>
    <collision>
      <origin xyz="-0.072 0.029 -0.0517" rpy="0 0 0"/>
      <geometry>
        <sphere radius="0.005"/>
      </geometry>
    </collision>
    <collision>
      <origin xyz="-0.072 -0.029 -0.0517" rpy="0 0 0"/>
      <geometry>
        <sphere radius="0.005"/>
      </geometry>
    </collision>
    <collision>
      <origin xyz="-0.047 0.039 -0.0517" rpy="0 0 0"/>
      <geometry>
        <sphere radius="0.005"/>
      </geometry>
    </collision>
    <collision>
      <origin xyz="-0.047 -0.039 -0.0517" rpy="0 0 0"/>
      <geometry>
        <sphere radius="0.005"/>
      </geometry>
    </collision>
    <collision>
      <origin xyz="-0.079 0 -0.0517" rpy="0 0 0"/>
      <geometry>
        <sphere radius="0.005"/>
      </geometry>
    </collision>

    <collision>
      <origin xyz="0.103 0.042 -0.0517" rpy="0 0 0"/>
      <geometry>
        <sphere radius="0.005"/>
      </geometry>
    </collision>
    <collision>
      <origin xyz="0.103 -0.042 -0.0517" rpy="0 0 0"/>
      <geometry>
        <sphere radius="0.005"/>
      </geometry>
    </collision>
    <collision>
      <origin xyz="0.158 0.034 -0.0517" rpy="0 0 0"/>
      <geometry>
        <sphere radius="0.005"/>
      </geometry>
    </collision>
    <collision>
      <origin xyz="0.158 -0.034 -0.0517" rpy="0 0 0"/>
      <geometry>
        <sphere radius="0.005"/>
      </geometry>
    </collision>
    <collision>
      <origin xyz="0.183 0 -0.0517" rpy="0 0 0"/>
      <geometry>
        <sphere radius="0.005"/>
      </geometry>
    </collision>
  </link>
  <joint name="L_ankle_roll_joint" type="revolute"><!-- EC-A8116-P1-18 -->
    <origin xyz="0 0 0" rpy="0 0 0" />
    <parent link="L_ankle_pitch_link" />
    <child link="L_ankle_roll_link" />
    <axis xyz="1 0 0" />
    <limit lower="-0.4363" upper="0.4363" effort="66" velocity="14.66" />
  </joint>
<!-- Right leg -->
  <link name="R_hip_roll_link">
    <inertial>
      <origin xyz="-0.021809 -2.71E-05 0.0049398" rpy="0 0 0" />
      <mass value="1.6267" />
      <inertia ixx="0.0019966" ixy="-1E-07" ixz="-0.0001016" iyy="0.0029305" iyz="2.9E-06" izz="0.003652" />
    </inertial>
    <visual>
      <origin xyz="0 0 0" rpy="0 0 0" />
      <geometry>
        <mesh filename="meshes/R_hip_roll_link.STL" />
      </geometry>
      <material name="">
        <color rgba="0.79216 0.81961 0.93333 1" />
      </material>
    </visual>
    <collision>
      <origin xyz="0 0 0" rpy="0 0 0" />
      <geometry>
        <cylinder radius="0.025" length="0.017"/>
      </geometry>
    </collision>
  </link>
  <joint name="R_hip_roll_joint" type="revolute"><!-- EC-A10020-P2-24 -->
    <origin xyz="0.0154 -0.125 -0.062997" rpy="0 0 0" />
    <parent link="pelvis_link" />
    <child link="R_hip_roll_link" />
    <axis xyz="1 0 0" />
    <limit lower="-0.83" upper="0.2" effort="130" velocity="12.88" />
  </joint>
  <link name="R_hip_yaw_link">
    <inertial>
      <origin xyz="-0.0005022 0.0012999 -0.1275315" rpy="0 0 0" />
      <mass value="3.6554644" />
      <inertia ixx="0.0120999" ixy="1.1E-06" ixz="0.0001282" iyy="0.0142817" iyz="5.48E-05" izz="0.0082633" />
    </inertial>
    <visual>
      <origin xyz="0 0 0" rpy="0 0 0" />
      <geometry>
        <mesh filename="meshes/R_hip_yaw_link.STL" />
      </geometry>
      <material name="">
        <color rgba="0.79216 0.81961 0.93333 1" />
      </material>
    </visual>
    <collision>
      <origin xyz="0 0 -0.14" rpy="1.570796327 0 0" />
      <geometry>
        <cylinder radius="0.025" length="0.04"/>
      </geometry>
    </collision>
  </link>
  <joint name="R_hip_yaw_joint" type="revolute"><!-- EC-A6416-P2-25 -->
    <origin xyz="0 0 0" rpy="0 0 0" />
    <parent link="R_hip_roll_link" />
    <child link="R_hip_yaw_link" />
    <axis xyz="0 0 1" />
    <limit lower="-0.78" upper="0.78" effort="55" velocity="12.56" />
  </joint>
  <link name="R_hip_pitch_link">
    <inertial>
      <origin xyz="0.0103759 -0.0011406 -0.1359260" rpy="0 0 0" />
      <mass value="2.0922344" />
      <inertia ixx="0.0346099" ixy="3.58E-05" ixz="0.000948" iyy="0.0332869" iyz="3.63E-05" izz="0.0089102" />
    </inertial>
    <visual>
      <origin xyz="0 0 0" rpy="0 0 0" />
      <geometry>
        <mesh filename="meshes/R_hip_pitch_link.STL" />
      </geometry>
      <material name="">
        <color rgba="0.79216 0.81961 0.93333 1" />
      </material>
    </visual>
    <collision>
      <origin xyz="0 0 -0.12" rpy="0 0 0" />
      <geometry>
        <cylinder radius="0.025" length="0.09"/>
      </geometry>
    </collision>
  </link>
  <joint name="R_hip_pitch_joint" type="revolute"><!-- EC-A10020-P2-24 -->
    <origin xyz="0 0 -0.14" rpy="0 0 0" />
    <parent link="R_hip_yaw_link" />
    <child link="R_hip_pitch_link" />
    <axis xyz="0 1 0" />
    <limit lower="-0.89" upper="1.64" effort="130" velocity="12.88" />
  </joint>
  <link name="R_knee_link">
    <inertial>
      <origin xyz="-0.0003539 -0.0004116 -0.1271738" rpy="0 0 0" />
      <mass value="7.502175" />
      <inertia ixx="0.1262274" ixy="-7.33E-05" ixz="-0.0034017" iyy="0.1314330" iyz="-0.0002212" izz="0.0155657" />
    </inertial>
    <visual>
      <origin xyz="0 0 0" rpy="0 0 0" />
      <geometry>
        <mesh filename="meshes/R_knee_link.STL" />
      </geometry>
      <material name="">
        <color rgba="0.79216 0.81961 0.93333 1" />
      </material>
    </visual>
    <collision>
      <origin xyz="0 0 -0.19" rpy="0 0 0" />
      <geometry>
        <cylinder radius="0.025" length="0.1"/>
      </geometry>
    </collision>
    <collision>
      <origin xyz="0 0 -0.35" rpy="0 0 0" />
      <geometry>
        <cylinder radius="0.025" length="0.1"/>
      </geometry>
    </collision>
    <collision>
      <origin xyz="0 0 0.0" rpy="1.570796327 0 0" />
      <geometry>
        <cylinder radius="0.025" length="0.1"/>
      </geometry>
    </collision>
  </link>
  <joint name="R_knee_joint" type="revolute"><!-- EC-A10020-P2-24 -->
    <origin xyz="0 0 -0.28502" rpy="0 0 0" />
    <parent link="R_hip_pitch_link" />
    <child link="R_knee_link" />
    <axis xyz="0 1 0" />
    <limit lower="-0.1" upper="2.3" effort="130" velocity="12.88" />
  </joint>
  <link name="R_ankle_pitch_link">
    <inertial>
      <origin xyz="-5.1137E-05 0 -0.002907" rpy="0 0 0" />
      <mass value="0.046143" />
      <inertia ixx="3.5529E-06" ixy="0" ixz="0" iyy="3.9072E-06" iyz="0" izz="3.3922E-06" />
    </inertial>
    <visual>
      <origin xyz="0 0 0" rpy="0 0 0" />
      <geometry>
        <mesh filename="meshes/R_ankle_pitch_link.STL" />
      </geometry>
      <material name="">
        <color rgba="0.79216 0.81961 0.93333 1" />
      </material>
    </visual>
    <collision>
      <origin xyz="0 0 0" rpy="0 0 0" />
      <geometry>
        <cylinder radius="0.001" length="0.001"/>
        <!-- <mesh filename="meshes/L_ankle_pitch_link.STL" /> -->
      </geometry>
    </collision>
  </link>
  <joint name="R_ankle_pitch_joint" type="revolute"><!-- EC-A8116-P1-18 -->
    <origin xyz="0 0 -0.452" rpy="0 0 0" />
    <parent link="R_knee_link" />
    <child link="R_ankle_pitch_link" />
    <axis xyz="0 1 0" />
    <limit lower="-0.52" upper="0.87" effort="66" velocity="14.66" />
  </joint>
  <link name="R_ankle_roll_link">
    <inertial>
      <origin xyz="0.031113 -1.04E-05 -0.032346" rpy="0 0 0" />
      <mass value="0.96254" />
      <inertia ixx="0.0007961" ixy="-2E-06" ixz="0.0006339" iyy="0.0056094" iyz="7E-07" izz="0.0057681" />
    </inertial>
    <visual>
      <origin xyz="0 0 0" rpy="0 0 0" />
      <geometry>
        <mesh filename="meshes/R_ankle_roll_link.STL" />
      </geometry>
      <material name="">
        <color rgba="0.79216 0.81961 0.93333 1" />
      </material>
    </visual>
    <collision>
      <origin xyz="-0.072 0.029 -0.0517" rpy="0 0 0"/>
      <geometry>
        <sphere radius="0.005"/>
      </geometry>
    </collision>
    <collision>
      <origin xyz="-0.072 -0.029 -0.0517" rpy="0 0 0"/>
      <geometry>
        <sphere radius="0.005"/>
      </geometry>
    </collision>
    <collision>
      <origin xyz="-0.047 0.039 -0.0517" rpy="0 0 0"/>
      <geometry>
        <sphere radius="0.005"/>
      </geometry>
    </collision>
    <collision>
      <origin xyz="-0.047 -0.039 -0.0517" rpy="0 0 0"/>
      <geometry>
        <sphere radius="0.005"/>
      </geometry>
    </collision>
    <collision>
      <origin xyz="-0.079 0 -0.0517" rpy="0 0 0"/>
      <geometry>
        <sphere radius="0.005"/>
      </geometry>
    </collision>

    <collision>
      <origin xyz="0.103 0.042 -0.0517" rpy="0 0 0"/>
      <geometry>
        <sphere radius="0.005"/>
      </geometry>
    </collision>
    <collision>
      <origin xyz="0.103 -0.042 -0.0517" rpy="0 0 0"/>
      <geometry>
        <sphere radius="0.005"/>
      </geometry>
    </collision>
    <collision>
      <origin xyz="0.158 0.034 -0.0517" rpy="0 0 0"/>
      <geometry>
        <sphere radius="0.005"/>
      </geometry>
    </collision>
    <collision>
      <origin xyz="0.158 -0.034 -0.0517" rpy="0 0 0"/>
      <geometry>
        <sphere radius="0.005"/>
      </geometry>
    </collision>
    <collision>
      <origin xyz="0.183 0 -0.0517" rpy="0 0 0"/>
      <geometry>
        <sphere radius="0.005"/>
      </geometry>
    </collision>
  </link>
  <joint name="R_ankle_roll_joint" type="revolute"><!-- EC-A8116-P1-18 -->
    <origin xyz="0 0 0" rpy="0 0 0" />
    <parent link="R_ankle_pitch_link" />
    <child link="R_ankle_roll_link" />
    <axis xyz="1 0 0" />
    <limit lower="-0.4363" upper="0.4363" effort="66" velocity="14.66" />
  </joint>

<!-- torso -->
  <link name="torso_link">
    <inertial>
      <origin xyz="0.0067502 -0.0038791 0.2416466" rpy="0 0 0" />
      <mass value="19.21" />
      <inertia ixx="0.3608826" ixy="0.0031392" ixz="0.0054081" iyy="0.3390589" iyz="-0.0023955" izz="0.1688720" />
    </inertial>
    <visual>
      <origin xyz="0 0 0" rpy="0 0 0" />
      <geometry>
        <mesh filename="meshes/torso_link.STL" />
      </geometry>
      <material name="">
        <color rgba="0.79216 0.81961 0.93333 1" />
      </material>
    </visual>
    <collision>
      <origin xyz="-0.01 0 0.25" rpy="0 0 0" />
      <geometry>
        <box size="0.25 0.16 0.37"/>
      </geometry>
    </collision>
  </link>
  <joint name="pelvis_joint" type="revolute"><!-- EC-A10020-P2-24 -->
    <origin xyz="0 0 0" rpy="0 0 0" />
    <child link="torso_link" />
    <parent link="pelvis_link" />
    <axis xyz="0 0 1" />
    <limit lower="-1.04" upper="1.04" effort="130" velocity="12.88" />
  </joint>
<!-- Left arm -->
  <link name="L_shoulder_pitch_link">
    <inertial>
      <origin xyz="0.0034819 -0.0052797 1.47E-05" rpy="0 0 0" />
      <mass value="1.35" />
      <inertia ixx="0.0016146" ixy="-1.99E-05" ixz="-1E-07" iyy="0.0012512" iyz="-2E-07" izz="0.0014304" />
    </inertial>
    <visual>
      <origin xyz="0 0 0" rpy="0 0 0" />
      <geometry>
        <mesh filename="meshes/L_shoulder_pitch_link.STL" />
      </geometry>
      <material name="">
        <color rgba="0.79216 0.81961 0.93333 1" />
      </material>
    </visual>
    <collision>
      <origin xyz="0 0 0" rpy="1.570796327 0 1.570796327"/>
      <geometry>
        <cylinder radius="0.025" length="0.03"/>
      </geometry>
    </collision>
  </link>
  <joint name="L_shoulder_pitch_joint" type="revolute"><!-- CRA-RI60-80 -->
    <origin xyz="0.015442 0.22168 0.37829" rpy="0.2618 0 0" />
    <parent link="torso_link" />
    <child link="L_shoulder_pitch_link" />
    <axis xyz="0 1 0" />
    <limit lower="-1.48" upper="1.48" effort="42" velocity="8.58" />
  </joint>
  <link name="L_shoulder_roll_link">
    <inertial>
      <origin xyz="0.0001178 0.0018666 -0.056296" rpy="0 0 0" />
      <mass value="0.55" />
      <inertia ixx="0.0014965" ixy="1E-07" ixz="-1.21E-05" iyy="0.0018786" iyz="8.8E-06" izz="0.0011623" />
    </inertial>
    <visual>
      <origin xyz="0 0 0" rpy="0 0 0" />
      <geometry>
        <mesh filename="meshes/L_shoulder_roll_link.STL" />
      </geometry>
      <material name="">
        <color rgba="0.79216 0.81961 0.93333 1" />
      </material>
    </visual>
    <collision>
      <origin xyz="0 -0.001 -0.09" rpy="-0.2618 0 0" />
      <geometry>
        <cylinder radius="0.02" length="0.03"/>
      </geometry>
    </collision>
  </link>
  <joint name="L_shoulder_roll_joint" type="revolute"><!-- CRA-RI60-80 -->
    <origin xyz="0 0 0" rpy="0 0 0" />
    <parent link="L_shoulder_pitch_link" />
    <child link="L_shoulder_roll_link" />
    <axis xyz="1 0 0" />
    <limit lower="-0.12" upper="3.17" effort="42" velocity="8.58" />
  </joint>
  <link name="L_shoulder_yaw_link">
    <inertial>
      <origin xyz="0.0030369 -0.000691 0.048579" rpy="0 0 1.570796327" />
      <mass value="1.95" />
      <inertia ixx="0.0059016" ixy="-2.9E-06" ixz="0.0002786" iyy="0.0057612" iyz="-6.3E-06" izz="0.0016272" />
    </inertial>
    <visual>
      <origin xyz="0 0 0" rpy="0 0 1.570796327" />
      <geometry>
        <mesh filename="meshes/L_shoulder_yaw_link.STL" />
      </geometry>
      <material name="">
        <color rgba="0.79216 0.81961 0.93333 1" />
      </material>
    </visual>
    <collision>
      <origin xyz="0 0 0.05" rpy="0 0 1.570796327" />
      <geometry>
        <cylinder radius="0.02" length="0.06"/>
      </geometry>
    </collision>
  </link>
  <joint name="L_shoulder_yaw_joint" type="revolute"><!-- CRA-RI50-70 -->
    <origin xyz="0 -0.043708 -0.2504" rpy="-0.2618 0 0" />
    <parent link="L_shoulder_roll_link" />
    <child link="L_shoulder_yaw_link" />
    <axis xyz="0 0 1" />
    <limit lower="-1.69" upper="1.69" effort="23" velocity="10.15" />
  </joint>
  <link name="L_elbow_link">
    <inertial>
      <origin xyz="-0.0013729 0.0051926 -0.01857" rpy="0 0 1.570796327" />
      <mass value="0.25" />
      <inertia ixx="0.0003112" ixy="-1.1E-06" ixz="1.1E-06" iyy="0.0005758" iyz="2.23E-05" izz="0.0005034" />
    </inertial>
    <visual>
      <origin xyz="0 0 0" rpy="0 0 1.570796327" />
      <geometry>
        <mesh filename="meshes/L_elbow_link.STL" />
      </geometry>
      <material name="">
        <color rgba="0.79216 0.81961 0.93333 1" />
      </material>
    </visual>
    <collision>
      <origin xyz="0 0 -0.02" rpy="0 0 1.570796327" />
      <geometry>
        <cylinder radius="0.02" length="0.03"/>
      </geometry>
    </collision>
  </link>
  <joint name="L_elbow_joint" type="revolute"><!-- CRA-RI50-70 -->
    <origin xyz="0 0 0" rpy="0 0 0" />
    <parent link="L_shoulder_yaw_link" />
    <child link="L_elbow_link" />
    <axis xyz="0 1 0" />
    <limit lower="-1.95" upper="0.87" effort="23" velocity="10.15" />
  </joint>
  <link name="L_forearm_yaw_link">
    <inertial>
      <origin xyz="0.0014016 0.0001246 0.09169" rpy="0 0 0" />
      <mass value="1.05" />
      <inertia ixx="0.0016627" ixy="3.5E-06" ixz="2.96E-05" iyy="0.001822" iyz="-5.7E-06" izz="0.0007356" />
    </inertial>
    <visual>
      <origin xyz="0 0 0" rpy="0 0 0" />
      <geometry>
        <mesh filename="meshes/L_forearm_yaw_link.STL" />
      </geometry>
      <material name="">
        <color rgba="0.79216 0.81961 0.93333 1" />
      </material>
    </visual>
    <collision>
      <origin xyz="0 0 0.082" rpy="0 0 0" />
      <geometry>
        <cylinder radius="0.025" length="0.03"/>
      </geometry>
    </collision>
  </link>
  <joint name="L_forearm_yaw_joint" type="revolute"><!-- CRA-RI40-52 -->
    <origin xyz="0 0 -0.211" rpy="0 0 0" />
    <parent link="L_elbow_link" />
    <child link="L_forearm_yaw_link" />
    <axis xyz="0 0 1" />
    <limit lower="-1.53" upper="1.53" effort="8.3" velocity="12.35" />
  </joint>
  <link name="L_wrist_roll_link">
    <inertial>
      <origin xyz="0 -0.0047393 -2.85E-05" rpy="0 0 0" />
      <mass value="0.25" />
      <inertia ixx="8.23E-05" ixy="0" ixz="0" iyy="5.6E-05" iyz="2E-07" izz="8.3E-05" />
    </inertial>
    <visual>
      <origin xyz="0 0 0" rpy="0 0 0" />
      <geometry>
        <mesh filename="meshes/L_wrist_roll_link.STL" />
      </geometry>
      <material name="">
        <color rgba="0.79216 0.81961 0.93333 1" />
      </material>
    </visual>
    <collision>
      <origin xyz="0 0 0" rpy="0 1.570796327 0" />
      <geometry>
        <cylinder radius="0.015" length="0.01"/>
      </geometry>
    </collision>
  </link>
  <joint name="L_wrist_roll_joint" type="revolute"><!-- CRA-RI30-40 -->
    <origin xyz="0 0 0" rpy="0 0 0" />
    <parent link="L_forearm_yaw_link" />
    <child link="L_wrist_roll_link" />
    <axis xyz="1 0 0" />
    <limit lower="-2.3" upper="1.39" effort="8.3" velocity="12.35" />
  </joint>
  <link name="L_wrist_pitch_link">
    <inertial>
      <origin xyz="8.81E-05 0.0081922 -0.051309" rpy="0 0 0" />
      <mass value="0.16" />
      <inertia ixx="0.0001452" ixy="-2E-07" ixz="2E-07" iyy="0.0001194" iyz="-4.49E-05" izz="6.56E-05" />
    </inertial>
    <visual>
      <origin xyz="0 0 0" rpy="0 0 0" />
      <geometry>
        <mesh filename="meshes/L_wrist_pitch_link.STL" />
      </geometry>
      <material name="">
        <color rgba="0.79216 0.81961 0.93333 1" />
      </material>
    </visual>
    <collision>
      <origin xyz="0 0 -0.16" rpy="0 0 0" />
      <geometry>
        <box size="0.06 0.03 0.18"/>
      </geometry>
    </collision>
  </link>
  <joint name="L_wrist_pitch_joint" type="revolute"><!-- CRA-RI30-40 -->
    <origin xyz="0 0 0" rpy="0 0 0" />
    <parent link="L_wrist_roll_link" />
    <child link="L_wrist_pitch_link" />
    <axis xyz="0 1 0" />
    <limit lower="-1.78" upper="1.67" effort="8.3" velocity="12.35" />
  </joint>
<!-- Right arm -->
  <link name="R_shoulder_pitch_link">
    <inertial>
      <origin xyz="0.003482 0.0052769 1.44E-05" rpy="0 0 0" />
      <mass value="1.35" />
      <inertia ixx="0.0016147" ixy="1.99E-05" ixz="-2E-07" iyy="0.0012512" iyz="2E-07" izz="0.0014303" />
    </inertial>
    <visual>
      <origin xyz="0 0 0" rpy="0 0 0" />
      <geometry>
        <mesh filename="meshes/R_shoulder_pitch_link.STL" />
      </geometry>
      <material name="">
        <color rgba="0.79216 0.81961 0.93333 1" />
      </material>
    </visual>
    <collision>
      <origin xyz="0 0 0" rpy="1.570796327 0 1.570796327"/>
      <geometry>
        <cylinder radius="0.025" length="0.03"/>
      </geometry>
    </collision>
  </link>
  <joint name="R_shoulder_pitch_joint" type="revolute"><!-- CRA-RI60-80 -->
    <origin xyz="0.015442 -0.22168 0.37829" rpy="-0.2618 0 0" />
    <parent link="torso_link" />
    <child link="R_shoulder_pitch_link" />
    <axis xyz="0 1 0" />
    <limit lower="-1.48" upper="1.48" effort="42" velocity="8.58" />
  </joint>
  <link name="R_shoulder_roll_link">
    <inertial>
      <origin xyz="0.00012 -0.0018541 -0.0563" rpy="0 0 0" />
      <mass value="0.55" />
      <inertia ixx="0.0014966" ixy="1E-07" ixz="-1.21E-05" iyy="0.0018788" iyz="-8.8E-06" izz="0.0011624" />
    </inertial>
    <visual>
      <origin xyz="0 0 0" rpy="0 0 0" />
      <geometry>
        <mesh filename="meshes/R_shoulder_roll_link.STL" />
      </geometry>
      <material name="">
        <color rgba="0.79216 0.81961 0.93333 1" />
      </material>
    </visual>
    <collision>
      <origin xyz="0 -0.001 -0.09" rpy="-0.2618 0 0" />
      <geometry>
        <cylinder radius="0.02" length="0.03"/>
      </geometry>
    </collision>
  </link>
  <joint name="R_shoulder_roll_joint" type="revolute"><!-- CRA-RI60-80 -->
    <origin xyz="0 0 0" rpy="0 0 0" />
    <parent link="R_shoulder_pitch_link" />
    <child link="R_shoulder_roll_link" />
    <axis xyz="1 0 0" />
    <limit lower="-3.17" upper="0.12" effort="42" velocity="8.58" />
  </joint>
  <link name="R_shoulder_yaw_link">
    <inertial>
      <origin xyz="0.0029659 0.0006795 0.04866" rpy="0 0 -1.570796327" />
      <mass value="1.95" />
      <inertia ixx="0.0059019" ixy="3.1E-06" ixz="0.0002791" iyy="0.0057618" iyz="6.1E-06" izz="0.0016275" />
    </inertial>
    <visual>
      <origin xyz="0 0 0" rpy="0 0 -1.570796327" />
      <geometry>
        <mesh filename="meshes/R_shoulder_yaw_link.STL" />
      </geometry>
      <material name="">
        <color rgba="0.79216 0.81961 0.93333 1" />
      </material>
    </visual>
    <collision>
      <origin xyz="0 0 0.05" rpy="0 0 1.570796327" />
      <geometry>
        <cylinder radius="0.02" length="0.06"/>
      </geometry>
    </collision>
  </link>
  <joint name="R_shoulder_yaw_joint" type="revolute"><!-- CRA-RI50-70 -->
    <origin xyz="0 0.043708 -0.2504" rpy="0.2618 0 0" />
    <parent link="R_shoulder_roll_link" />
    <child link="R_shoulder_yaw_link" />
    <axis xyz="0 0 1" />
    <limit lower="-1.69" upper="1.69" effort="23" velocity="10.15" />
  </joint>
  <link name="R_elbow_link">
    <inertial>
      <origin xyz="-0.0013805 -0.0051935 -0.018572" rpy="0 0 -1.570796327" />
      <mass value="0.25" />
      <inertia ixx="0.0003112" ixy="1.1E-06" ixz="1.1E-06" iyy="0.0005757" iyz="-2.23E-05" izz="0.0005034" />
    </inertial>
    <visual>
      <origin xyz="0 0 0" rpy="0 0 -1.570796327" />
      <geometry>
        <mesh filename="meshes/R_elbow_link.STL" />
      </geometry>
      <material name="">
        <color rgba="0.79216 0.81961 0.93333 1" />
      </material>
    </visual>
    <collision>
      <origin xyz="0 0 -0.02" rpy="0 0 1.570796327" />
      <geometry>
        <cylinder radius="0.02" length="0.03"/>
      </geometry>
    </collision>
  </link>
  <joint name="R_elbow_joint" type="revolute"><!-- CRA-RI50-70 -->
    <origin xyz="0 0 0" rpy="0 0 0" />
    <parent link="R_shoulder_yaw_link" />
    <child link="R_elbow_link" />
    <axis xyz="0 1 0" />
    <limit lower="-0.87" upper="1.95" effort="23" velocity="10.15" />
  </joint>
  <link name="R_forearm_yaw_link">
    <inertial>
      <origin xyz="0.0014 -0.0001237 0.09169" rpy="0 0 0" />
      <mass value="1.05" />
      <inertia ixx="0.0016625" ixy="-3.5E-06" ixz="2.96E-05" iyy="0.0018219" iyz="5.7E-06" izz="0.0007357" />
    </inertial>
    <visual>
      <origin xyz="0 0 0" rpy="0 0 0" />
      <geometry>
        <mesh filename="meshes/R_forearm_yaw_link.STL" />
      </geometry>
      <material name="">
        <color rgba="0.79216 0.81961 0.93333 1" />
      </material>
    </visual>
    <collision>
      <origin xyz="0 0 0.082" rpy="0 0 0" />
      <geometry>
        <cylinder radius="0.025" length="0.03"/>
      </geometry>
    </collision>
  </link>
  <joint name="R_forearm_yaw_joint" type="revolute"><!-- CRA-RI40-52 -->
    <origin xyz="0 0 -0.211" rpy="0 0 0" />
    <parent link="R_elbow_link" />
    <child link="R_forearm_yaw_link" />
    <axis xyz="0 0 1" />
    <limit lower="-1.53" upper="1.53" effort="8.3" velocity="12.35" />
  </joint>
  <link name="R_wrist_roll_link">
    <inertial>
      <origin xyz="0 0.0047393 -2.85E-05" rpy="0 0 0" />
      <mass value="0.25" />
      <inertia ixx="8.23E-05" ixy="0" ixz="0" iyy="5.6E-05" iyz="-2E-07" izz="8.3E-05" />
    </inertial>
    <visual>
      <origin xyz="0 0 0" rpy="0 0 0" />
      <geometry>
        <mesh filename="meshes/R_wrist_roll_link.STL" />
      </geometry>
      <material name="">
        <color rgba="0.79216 0.81961 0.93333 1" />
      </material>
    </visual>
    <collision>
      <origin xyz="0 0 0" rpy="0 1.570796327 0" />
      <geometry>
        <cylinder radius="0.015" length="0.01"/>
      </geometry>
    </collision>
  </link>
  <joint name="R_wrist_roll_joint" type="revolute"><!-- CRA-RI40-52 -->
    <origin xyz="0 0 0" rpy="0 0 0" />
    <parent link="R_forearm_yaw_link" />
    <child link="R_wrist_roll_link" />
    <axis xyz="1 0 0" />
    <limit lower="-1.39" upper="2.3" effort="8.3" velocity="12.35" />
  </joint>
  <link name="R_wrist_pitch_link">
    <inertial>
      <origin xyz="8.81E-05 -0.0081922 -0.051309" rpy="0 0 0" />
      <mass value="0.16" />
      <inertia ixx="0.0001452" ixy="2E-07" ixz="2E-07" iyy="0.0001194" iyz="4.49E-05" izz="6.56E-05" />
    </inertial>
    <visual>
      <origin xyz="0 0 0" rpy="0 0 0" />
      <geometry>
        <mesh filename="meshes/R_wrist_pitch_link.STL" />
      </geometry>
      <material name="">
        <color rgba="0.79216 0.81961 0.93333 1" />
      </material>
    </visual>
    <collision>
      <origin xyz="0 0 -0.16" rpy="0 0 0" />
      <geometry>
        <box size="0.06 0.03 0.18"/>
      </geometry>
    </collision>
  </link>
  <joint name="R_wrist_pitch_joint" type="revolute"><!-- CRA-RI30-40 -->
    <origin xyz="0 0 0" rpy="0 0 0" />
    <parent link="R_wrist_roll_link" />
    <child link="R_wrist_pitch_link" />
    <axis xyz="0 1 0" />
    <limit lower="-1.78" upper="1.67" effort="8.3" velocity="12.35" />
  </joint>
<!-- Head -->
  <link name="head_yaw_link">
    <inertial>
      <origin xyz="9.42E-05 -0.0015802 -0.0048308" rpy="0 0 0" />
      <mass value="0.8" />
      <inertia ixx="0.0023797" ixy="-5E-07" ixz="7E-07" iyy="0.0005019" iyz="5.7E-06" izz="0.0023519" />
    </inertial>
    <visual>
      <origin xyz="0 0 0" rpy="0 0 0" />
      <geometry>
        <mesh filename="meshes/head_yaw_link.STL" />
      </geometry>
      <material name="">
        <color rgba="0.79216 0.81961 0.93333 1" />
      </material>
    </visual>
    <collision>
      <origin xyz="0 0 0" rpy="0 0 0" />
      <geometry>
        <mesh filename="meshes/head_yaw_link.STL" />
      </geometry>
    </collision>
  </link>
  <joint name="head_yaw_joint" type="revolute">
    <origin xyz="0.026942 0 0.61493" rpy="0 0 0" />
    <parent link="torso_link" />
    <child link="head_yaw_link" />
    <axis xyz="0 0 1" />
    <limit lower="-1.57" upper="1.57" effort="2.52" velocity="29.21" />
  </joint>
  <link name="head_pitch_link">
    <inertial>
      <origin xyz="0.021366 0.0020556 0.027951" rpy="0 0 0" />
      <mass value="0.72904" />
      <inertia ixx="0.0033823" ixy="4.5E-05" ixz="0.0004603" iyy="0.0044162" iyz="3.21E-05" izz="0.0042325" />
    </inertial>
    <visual>
      <origin xyz="0 0 0" rpy="0 0 0" />
      <geometry>
        <mesh filename="meshes/head_pitch_link.STL" />
      </geometry>
      <material name="">
        <color rgba="0.79216 0.81961 0.93333 1" />
      </material>
    </visual>
    <collision>
      <origin xyz="0 0 0" rpy="0 0 0" />
      <geometry>
        <mesh filename="meshes/head_pitch_link.STL" />
      </geometry>
    </collision>
  </link>
  <joint name="head_pitch_joint" type="revolute">
    <origin xyz="0 0 0" rpy="0 0 0" />
    <parent link="head_yaw_link" />
    <child link="head_pitch_link" />
    <axis xyz="0 1 0" />
    <limit lower="-0.38" upper="0.33" effort="2.52" velocity="29.21" />
  </joint>
</robot>